2022-06-20 13:39:22,912 - [WARNING] -  aiogram - (executor.py).start_polling(329) - Goodbye!
2022-06-20 13:40:17,043 - [WARNING] - [aiogram(executor.py) - start_polling329] - Goodbye!
[MainProcess:14758] [MainThread:4343448960] - /Users/sammuurr/PycharmProjects/GeekShop/venv/lib/python3.9/site-packages/aiogram/utils/executor.py
2022-06-20 13:40:27,279 - [WARNING] - [aiogram(executor.py) - start_polling329] - Goodbye!
[MainProcess:14785] [MainThread:4378756480] - /Users/sammuurr/PycharmProjects/GeekShop/venv/lib/python3.9/site-packages/aiogram/utils/executor.py



2022-06-20 13:40:43,977 - [WARNING] - [aiogram(executor.py) - start_polling329] - Goodbye!
[MainProcess:14796] [MainThread:4365682048] - /Users/sammuurr/PycharmProjects/GeekShop/venv/lib/python3.9/site-packages/aiogram/utils/executor.py


2022-06-20 13:41:43,617 - [WARNING] - [aiogram(executor.py) - start_polling329] - Goodbye!
[MainProcess:14805] [MainThread:4373448064] - /Users/sammuurr/PycharmProjects/GeekShop/venv/lib/python3.9/site-packages/aiogram/utils/executor.py

[2022-06-20 13:43:44,303] - [WARNING] - [aiogram(executor.py) - start_polling329] - Goodbye!
[MainProcess:14827] [MainThread:4308272512] - /Users/sammuurr/PycharmProjects/GeekShop/venv/lib/python3.9/site-packages/aiogram/utils/executor.py

[2022-06-20 13:44:26,208] - [WARNING] - [aiogram(executor.py) - start_polling329] - Goodbye!
[MainProcess:14857] [MainThread:4381836672] - /Users/sammuurr/PycharmProjects/GeekShop/venv/lib/python3.9/site-packages/aiogram/utils/executor.py

[2022-06-20 13:44:47,929] - [WARNING] - [aiogram(executor.py) - start_polling329] - Goodbye!
[MainProcess:14884] [MainThread:4310943104] - /Users/sammuurr/PycharmProjects/GeekShop/venv/lib/python3.9/site-packages/aiogram/utils/executor.py

[2022-06-20 14:01:26,539] - [WARNING] - [aiogram(executor.py) - start_polling329] - Goodbye!
[MainProcess:14897] [MainThread:4365419904] - /Users/sammuurr/PycharmProjects/GeekShop/venv/lib/python3.9/site-packages/aiogram/utils/executor.py

[2022-06-20 14:07:31,964] - [WARNING] -->  Goodbye!
[2022-06-20 14:09:32,640] - [WARNING] -->  Goodbye!
[2022-06-20 14:10:20,901] - [WARNING] -->  Goodbye!
[2022-06-20 14:11:51,486] - [WARNING] -->  Goodbye!
[2022-06-20 16:04:33,330] - [ERROR] -->  Cause exception while getting updates.
Traceback (most recent call last):
  File "/Users/sammuurr/PycharmProjects/GeekShop/venv/lib/python3.9/site-packages/aiogram/dispatcher/dispatcher.py", line 381, in start_polling
    updates = await self.bot.get_updates(
  File "/Users/sammuurr/PycharmProjects/GeekShop/venv/lib/python3.9/site-packages/aiogram/bot/bot.py", line 110, in get_updates
    result = await self.request(api.Methods.GET_UPDATES, payload)
  File "/Users/sammuurr/PycharmProjects/GeekShop/venv/lib/python3.9/site-packages/aiogram/bot/base.py", line 231, in request
    return await api.make_request(await self.get_session(), self.server, self.__token, method, data, files,
  File "/Users/sammuurr/PycharmProjects/GeekShop/venv/lib/python3.9/site-packages/aiogram/bot/api.py", line 139, in make_request
    async with session.post(url, data=req, **kwargs) as response:
  File "/Users/sammuurr/PycharmProjects/GeekShop/venv/lib/python3.9/site-packages/aiohttp/client.py", line 1138, in __aenter__
    self._resp = await self._coro
  File "/Users/sammuurr/PycharmProjects/GeekShop/venv/lib/python3.9/site-packages/aiohttp/client.py", line 559, in _request
    await resp.start(conn)
  File "/Users/sammuurr/PycharmProjects/GeekShop/venv/lib/python3.9/site-packages/aiohttp/client_reqrep.py", line 913, in start
    self._continue = None
  File "/Users/sammuurr/PycharmProjects/GeekShop/venv/lib/python3.9/site-packages/aiohttp/helpers.py", line 721, in __exit__
    raise asyncio.TimeoutError from None
asyncio.exceptions.TimeoutError
[2022-06-20 16:10:00,080] - [WARNING] -->  Goodbye!
[2022-06-20 16:15:02,335] - [ERROR] -->  Cause exception while getting updates.
Traceback (most recent call last):
  File "/Users/sammuurr/PycharmProjects/GeekShop/venv/lib/python3.9/site-packages/aiogram/dispatcher/dispatcher.py", line 381, in start_polling
    updates = await self.bot.get_updates(
  File "/Users/sammuurr/PycharmProjects/GeekShop/venv/lib/python3.9/site-packages/aiogram/bot/bot.py", line 110, in get_updates
    result = await self.request(api.Methods.GET_UPDATES, payload)
  File "/Users/sammuurr/PycharmProjects/GeekShop/venv/lib/python3.9/site-packages/aiogram/bot/base.py", line 231, in request
    return await api.make_request(await self.get_session(), self.server, self.__token, method, data, files,
  File "/Users/sammuurr/PycharmProjects/GeekShop/venv/lib/python3.9/site-packages/aiogram/bot/api.py", line 139, in make_request
    async with session.post(url, data=req, **kwargs) as response:
  File "/Users/sammuurr/PycharmProjects/GeekShop/venv/lib/python3.9/site-packages/aiohttp/client.py", line 1138, in __aenter__
    self._resp = await self._coro
  File "/Users/sammuurr/PycharmProjects/GeekShop/venv/lib/python3.9/site-packages/aiohttp/client.py", line 559, in _request
    await resp.start(conn)
  File "/Users/sammuurr/PycharmProjects/GeekShop/venv/lib/python3.9/site-packages/aiohttp/client_reqrep.py", line 913, in start
    self._continue = None
  File "/Users/sammuurr/PycharmProjects/GeekShop/venv/lib/python3.9/site-packages/aiohttp/helpers.py", line 721, in __exit__
    raise asyncio.TimeoutError from None
asyncio.exceptions.TimeoutError
[2022-06-20 16:19:13,902] - [WARNING] -->  Goodbye!
[2022-06-20 22:46:24,451] - [ERROR] -->  Cause exception while getting updates.
Traceback (most recent call last):
  File "/Users/sammuurr/PycharmProjects/GeekShop/venv/lib/python3.9/site-packages/aiogram/dispatcher/dispatcher.py", line 381, in start_polling
    updates = await self.bot.get_updates(
  File "/Users/sammuurr/PycharmProjects/GeekShop/venv/lib/python3.9/site-packages/aiogram/bot/bot.py", line 110, in get_updates
    result = await self.request(api.Methods.GET_UPDATES, payload)
  File "/Users/sammuurr/PycharmProjects/GeekShop/venv/lib/python3.9/site-packages/aiogram/bot/base.py", line 231, in request
    return await api.make_request(await self.get_session(), self.server, self.__token, method, data, files,
  File "/Users/sammuurr/PycharmProjects/GeekShop/venv/lib/python3.9/site-packages/aiogram/bot/api.py", line 139, in make_request
    async with session.post(url, data=req, **kwargs) as response:
  File "/Users/sammuurr/PycharmProjects/GeekShop/venv/lib/python3.9/site-packages/aiohttp/client.py", line 1138, in __aenter__
    self._resp = await self._coro
  File "/Users/sammuurr/PycharmProjects/GeekShop/venv/lib/python3.9/site-packages/aiohttp/client.py", line 559, in _request
    await resp.start(conn)
  File "/Users/sammuurr/PycharmProjects/GeekShop/venv/lib/python3.9/site-packages/aiohttp/client_reqrep.py", line 913, in start
    self._continue = None
  File "/Users/sammuurr/PycharmProjects/GeekShop/venv/lib/python3.9/site-packages/aiohttp/helpers.py", line 721, in __exit__
    raise asyncio.TimeoutError from None
asyncio.exceptions.TimeoutError
[2022-06-20 23:33:52,772] - [WARNING] -->  Goodbye!
[2022-06-21 00:00:26,601] - [WARNING] -->  Goodbye!
[2022-06-21 00:05:50,113] - [WARNING] -->  Goodbye!
[2022-06-21 00:09:29,504] - [WARNING] -->  Goodbye!
[2022-06-21 00:38:03,637] - [ERROR] -->  Cause exception while getting updates.
Traceback (most recent call last):
  File "/Users/sammuurr/PycharmProjects/GeekShop/venv/lib/python3.9/site-packages/aiogram/dispatcher/dispatcher.py", line 381, in start_polling
    updates = await self.bot.get_updates(
  File "/Users/sammuurr/PycharmProjects/GeekShop/venv/lib/python3.9/site-packages/aiogram/bot/bot.py", line 110, in get_updates
    result = await self.request(api.Methods.GET_UPDATES, payload)
  File "/Users/sammuurr/PycharmProjects/GeekShop/venv/lib/python3.9/site-packages/aiogram/bot/base.py", line 231, in request
    return await api.make_request(await self.get_session(), self.server, self.__token, method, data, files,
  File "/Users/sammuurr/PycharmProjects/GeekShop/venv/lib/python3.9/site-packages/aiogram/bot/api.py", line 139, in make_request
    async with session.post(url, data=req, **kwargs) as response:
  File "/Users/sammuurr/PycharmProjects/GeekShop/venv/lib/python3.9/site-packages/aiohttp/client.py", line 1138, in __aenter__
    self._resp = await self._coro
  File "/Users/sammuurr/PycharmProjects/GeekShop/venv/lib/python3.9/site-packages/aiohttp/client.py", line 559, in _request
    await resp.start(conn)
  File "/Users/sammuurr/PycharmProjects/GeekShop/venv/lib/python3.9/site-packages/aiohttp/client_reqrep.py", line 913, in start
    self._continue = None
  File "/Users/sammuurr/PycharmProjects/GeekShop/venv/lib/python3.9/site-packages/aiohttp/helpers.py", line 721, in __exit__
    raise asyncio.TimeoutError from None
asyncio.exceptions.TimeoutError
[2022-06-21 01:06:27,211] - [WARNING] -->  Goodbye!
[2022-06-21 01:09:35,898] - [ERROR] -->  Task exception was never retrieved
future: <Task finished name='Task-20' coro=<Dispatcher._process_polling_updates() done, defined at /Users/sammuurr/PycharmProjects/GeekShop/venv/lib/python3.9/site-packages/aiogram/dispatcher/dispatcher.py:407> exception=IndexError('list index out of range')>
Traceback (most recent call last):
  File "/Users/sammuurr/PycharmProjects/GeekShop/venv/lib/python3.9/site-packages/aiogram/dispatcher/dispatcher.py", line 415, in _process_polling_updates
    for responses in itertools.chain.from_iterable(await self.process_updates(updates, fast)):
  File "/Users/sammuurr/PycharmProjects/GeekShop/venv/lib/python3.9/site-packages/aiogram/dispatcher/dispatcher.py", line 235, in process_updates
    return await asyncio.gather(*tasks)
  File "/Users/sammuurr/PycharmProjects/GeekShop/venv/lib/python3.9/site-packages/aiogram/dispatcher/handler.py", line 116, in notify
    response = await handler_obj.handler(*args, **partial_data)
  File "/Users/sammuurr/PycharmProjects/GeekShop/venv/lib/python3.9/site-packages/aiogram/dispatcher/dispatcher.py", line 256, in process_update
    return await self.message_handlers.notify(update.message)
  File "/Users/sammuurr/PycharmProjects/GeekShop/venv/lib/python3.9/site-packages/aiogram/dispatcher/handler.py", line 116, in notify
    response = await handler_obj.handler(*args, **partial_data)
  File "/Users/sammuurr/PycharmProjects/GeekShop/handlers/command_handlers/admin.py", line 13, in process_admin_command
    if message.from_user.id in admins[0]:
IndexError: list index out of range
[2022-06-21 01:09:38,207] - [ERROR] -->  Task exception was never retrieved
future: <Task finished name='Task-23' coro=<Dispatcher._process_polling_updates() done, defined at /Users/sammuurr/PycharmProjects/GeekShop/venv/lib/python3.9/site-packages/aiogram/dispatcher/dispatcher.py:407> exception=IndexError('list index out of range')>
Traceback (most recent call last):
  File "/Users/sammuurr/PycharmProjects/GeekShop/venv/lib/python3.9/site-packages/aiogram/dispatcher/dispatcher.py", line 415, in _process_polling_updates
    for responses in itertools.chain.from_iterable(await self.process_updates(updates, fast)):
  File "/Users/sammuurr/PycharmProjects/GeekShop/venv/lib/python3.9/site-packages/aiogram/dispatcher/dispatcher.py", line 235, in process_updates
    return await asyncio.gather(*tasks)
  File "/Users/sammuurr/PycharmProjects/GeekShop/venv/lib/python3.9/site-packages/aiogram/dispatcher/handler.py", line 116, in notify
    response = await handler_obj.handler(*args, **partial_data)
  File "/Users/sammuurr/PycharmProjects/GeekShop/venv/lib/python3.9/site-packages/aiogram/dispatcher/dispatcher.py", line 256, in process_update
    return await self.message_handlers.notify(update.message)
  File "/Users/sammuurr/PycharmProjects/GeekShop/venv/lib/python3.9/site-packages/aiogram/dispatcher/handler.py", line 116, in notify
    response = await handler_obj.handler(*args, **partial_data)
  File "/Users/sammuurr/PycharmProjects/GeekShop/handlers/command_handlers/admin.py", line 13, in process_admin_command
    if message.from_user.id in admins[0]:
IndexError: list index out of range
[2022-06-21 01:10:27,702] - [WARNING] -->  Goodbye!
[2022-06-21 01:10:32,551] - [ERROR] -->  Task exception was never retrieved
future: <Task finished name='Task-7' coro=<Dispatcher._process_polling_updates() done, defined at /Users/sammuurr/PycharmProjects/GeekShop/venv/lib/python3.9/site-packages/aiogram/dispatcher/dispatcher.py:407> exception=IndexError('list index out of range')>
Traceback (most recent call last):
  File "/Users/sammuurr/PycharmProjects/GeekShop/venv/lib/python3.9/site-packages/aiogram/dispatcher/dispatcher.py", line 415, in _process_polling_updates
    for responses in itertools.chain.from_iterable(await self.process_updates(updates, fast)):
  File "/Users/sammuurr/PycharmProjects/GeekShop/venv/lib/python3.9/site-packages/aiogram/dispatcher/dispatcher.py", line 235, in process_updates
    return await asyncio.gather(*tasks)
  File "/Users/sammuurr/PycharmProjects/GeekShop/venv/lib/python3.9/site-packages/aiogram/dispatcher/handler.py", line 116, in notify
    response = await handler_obj.handler(*args, **partial_data)
  File "/Users/sammuurr/PycharmProjects/GeekShop/venv/lib/python3.9/site-packages/aiogram/dispatcher/dispatcher.py", line 256, in process_update
    return await self.message_handlers.notify(update.message)
  File "/Users/sammuurr/PycharmProjects/GeekShop/venv/lib/python3.9/site-packages/aiogram/dispatcher/handler.py", line 116, in notify
    response = await handler_obj.handler(*args, **partial_data)
  File "/Users/sammuurr/PycharmProjects/GeekShop/handlers/command_handlers/admin.py", line 14, in process_admin_command
    if message.from_user.id in admins[0]:
IndexError: list index out of range
[2022-06-21 01:14:18,650] - [WARNING] -->  Goodbye!
[2022-06-21 01:37:39,997] - [WARNING] -->  Goodbye!
[2022-06-21 01:41:45,479] - [WARNING] -->  Goodbye!
[2022-06-21 01:41:51,765] - [ERROR] -->  Task exception was never retrieved
future: <Task finished name='Task-7' coro=<Dispatcher._process_polling_updates() done, defined at /Users/sammuurr/PycharmProjects/GeekShop/venv/lib/python3.9/site-packages/aiogram/dispatcher/dispatcher.py:407> exception=CantParseEntities("Can't parse entities: can't find end tag corresponding to start tag i")>
Traceback (most recent call last):
  File "/Users/sammuurr/PycharmProjects/GeekShop/venv/lib/python3.9/site-packages/aiogram/dispatcher/dispatcher.py", line 415, in _process_polling_updates
    for responses in itertools.chain.from_iterable(await self.process_updates(updates, fast)):
  File "/Users/sammuurr/PycharmProjects/GeekShop/venv/lib/python3.9/site-packages/aiogram/dispatcher/dispatcher.py", line 235, in process_updates
    return await asyncio.gather(*tasks)
  File "/Users/sammuurr/PycharmProjects/GeekShop/venv/lib/python3.9/site-packages/aiogram/dispatcher/handler.py", line 116, in notify
    response = await handler_obj.handler(*args, **partial_data)
  File "/Users/sammuurr/PycharmProjects/GeekShop/venv/lib/python3.9/site-packages/aiogram/dispatcher/dispatcher.py", line 256, in process_update
    return await self.message_handlers.notify(update.message)
  File "/Users/sammuurr/PycharmProjects/GeekShop/venv/lib/python3.9/site-packages/aiogram/dispatcher/handler.py", line 116, in notify
    response = await handler_obj.handler(*args, **partial_data)
  File "/Users/sammuurr/PycharmProjects/GeekShop/handlers/command_handlers/start.py", line 13, in process_start_command
    await bot.send_message(
  File "/Users/sammuurr/PycharmProjects/GeekShop/venv/lib/python3.9/site-packages/aiogram/bot/bot.py", line 334, in send_message
    result = await self.request(api.Methods.SEND_MESSAGE, payload)
  File "/Users/sammuurr/PycharmProjects/GeekShop/venv/lib/python3.9/site-packages/aiogram/bot/base.py", line 231, in request
    return await api.make_request(await self.get_session(), self.server, self.__token, method, data, files,
  File "/Users/sammuurr/PycharmProjects/GeekShop/venv/lib/python3.9/site-packages/aiogram/bot/api.py", line 140, in make_request
    return check_result(method, response.content_type, response.status, await response.text())
  File "/Users/sammuurr/PycharmProjects/GeekShop/venv/lib/python3.9/site-packages/aiogram/bot/api.py", line 115, in check_result
    exceptions.BadRequest.detect(description)
  File "/Users/sammuurr/PycharmProjects/GeekShop/venv/lib/python3.9/site-packages/aiogram/utils/exceptions.py", line 140, in detect
    raise err(cls.text or description)
aiogram.utils.exceptions.CantParseEntities: Can't parse entities: can't find end tag corresponding to start tag i
[2022-06-21 01:44:19,353] - [WARNING] -->  Goodbye!
[2022-06-21 01:44:24,393] - [ERROR] -->  Task exception was never retrieved
future: <Task finished name='Task-7' coro=<Dispatcher._process_polling_updates() done, defined at /Users/sammuurr/PycharmProjects/GeekShop/venv/lib/python3.9/site-packages/aiogram/dispatcher/dispatcher.py:407> exception=CantParseEntities("Can't parse entities: can't find end tag corresponding to start tag i")>
Traceback (most recent call last):
  File "/Users/sammuurr/PycharmProjects/GeekShop/venv/lib/python3.9/site-packages/aiogram/dispatcher/dispatcher.py", line 415, in _process_polling_updates
    for responses in itertools.chain.from_iterable(await self.process_updates(updates, fast)):
  File "/Users/sammuurr/PycharmProjects/GeekShop/venv/lib/python3.9/site-packages/aiogram/dispatcher/dispatcher.py", line 235, in process_updates
    return await asyncio.gather(*tasks)
  File "/Users/sammuurr/PycharmProjects/GeekShop/venv/lib/python3.9/site-packages/aiogram/dispatcher/handler.py", line 116, in notify
    response = await handler_obj.handler(*args, **partial_data)
  File "/Users/sammuurr/PycharmProjects/GeekShop/venv/lib/python3.9/site-packages/aiogram/dispatcher/dispatcher.py", line 256, in process_update
    return await self.message_handlers.notify(update.message)
  File "/Users/sammuurr/PycharmProjects/GeekShop/venv/lib/python3.9/site-packages/aiogram/dispatcher/handler.py", line 116, in notify
    response = await handler_obj.handler(*args, **partial_data)
  File "/Users/sammuurr/PycharmProjects/GeekShop/handlers/command_handlers/start.py", line 13, in process_start_command
    await bot.send_message(
  File "/Users/sammuurr/PycharmProjects/GeekShop/venv/lib/python3.9/site-packages/aiogram/bot/bot.py", line 334, in send_message
    result = await self.request(api.Methods.SEND_MESSAGE, payload)
  File "/Users/sammuurr/PycharmProjects/GeekShop/venv/lib/python3.9/site-packages/aiogram/bot/base.py", line 231, in request
    return await api.make_request(await self.get_session(), self.server, self.__token, method, data, files,
  File "/Users/sammuurr/PycharmProjects/GeekShop/venv/lib/python3.9/site-packages/aiogram/bot/api.py", line 140, in make_request
    return check_result(method, response.content_type, response.status, await response.text())
  File "/Users/sammuurr/PycharmProjects/GeekShop/venv/lib/python3.9/site-packages/aiogram/bot/api.py", line 115, in check_result
    exceptions.BadRequest.detect(description)
  File "/Users/sammuurr/PycharmProjects/GeekShop/venv/lib/python3.9/site-packages/aiogram/utils/exceptions.py", line 140, in detect
    raise err(cls.text or description)
aiogram.utils.exceptions.CantParseEntities: Can't parse entities: can't find end tag corresponding to start tag i
[2022-06-21 01:45:05,633] - [WARNING] -->  Goodbye!
[2022-06-21 01:45:09,788] - [ERROR] -->  Task exception was never retrieved
future: <Task finished name='Task-7' coro=<Dispatcher._process_polling_updates() done, defined at /Users/sammuurr/PycharmProjects/GeekShop/venv/lib/python3.9/site-packages/aiogram/dispatcher/dispatcher.py:407> exception=CantParseEntities("Can't parse entities: can't find end tag corresponding to start tag em")>
Traceback (most recent call last):
  File "/Users/sammuurr/PycharmProjects/GeekShop/venv/lib/python3.9/site-packages/aiogram/dispatcher/dispatcher.py", line 415, in _process_polling_updates
    for responses in itertools.chain.from_iterable(await self.process_updates(updates, fast)):
  File "/Users/sammuurr/PycharmProjects/GeekShop/venv/lib/python3.9/site-packages/aiogram/dispatcher/dispatcher.py", line 235, in process_updates
    return await asyncio.gather(*tasks)
  File "/Users/sammuurr/PycharmProjects/GeekShop/venv/lib/python3.9/site-packages/aiogram/dispatcher/handler.py", line 116, in notify
    response = await handler_obj.handler(*args, **partial_data)
  File "/Users/sammuurr/PycharmProjects/GeekShop/venv/lib/python3.9/site-packages/aiogram/dispatcher/dispatcher.py", line 256, in process_update
    return await self.message_handlers.notify(update.message)
  File "/Users/sammuurr/PycharmProjects/GeekShop/venv/lib/python3.9/site-packages/aiogram/dispatcher/handler.py", line 116, in notify
    response = await handler_obj.handler(*args, **partial_data)
  File "/Users/sammuurr/PycharmProjects/GeekShop/handlers/command_handlers/start.py", line 13, in process_start_command
    await bot.send_message(
  File "/Users/sammuurr/PycharmProjects/GeekShop/venv/lib/python3.9/site-packages/aiogram/bot/bot.py", line 334, in send_message
    result = await self.request(api.Methods.SEND_MESSAGE, payload)
  File "/Users/sammuurr/PycharmProjects/GeekShop/venv/lib/python3.9/site-packages/aiogram/bot/base.py", line 231, in request
    return await api.make_request(await self.get_session(), self.server, self.__token, method, data, files,
  File "/Users/sammuurr/PycharmProjects/GeekShop/venv/lib/python3.9/site-packages/aiogram/bot/api.py", line 140, in make_request
    return check_result(method, response.content_type, response.status, await response.text())
  File "/Users/sammuurr/PycharmProjects/GeekShop/venv/lib/python3.9/site-packages/aiogram/bot/api.py", line 115, in check_result
    exceptions.BadRequest.detect(description)
  File "/Users/sammuurr/PycharmProjects/GeekShop/venv/lib/python3.9/site-packages/aiogram/utils/exceptions.py", line 140, in detect
    raise err(cls.text or description)
aiogram.utils.exceptions.CantParseEntities: Can't parse entities: can't find end tag corresponding to start tag em
[2022-06-21 01:47:08,661] - [WARNING] -->  Goodbye!
[2022-06-21 01:55:59,228] - [WARNING] -->  Goodbye!
[2022-06-21 01:56:19,351] - [ERROR] -->  Task exception was never retrieved
future: <Task finished name='Task-11' coro=<Dispatcher._process_polling_updates() done, defined at /Users/sammuurr/PycharmProjects/GeekShop/venv/lib/python3.9/site-packages/aiogram/dispatcher/dispatcher.py:407> exception=IndexError('list index out of range')>
Traceback (most recent call last):
  File "/Users/sammuurr/PycharmProjects/GeekShop/handlers/inline_handlers/admin_menu/admin_menu_admins.py", line 35, in enter_add_newadmin
    await bot.send_message(
TypeError: send_message() got an unexpected keyword argument 'id'

During handling of the above exception, another exception occurred:

Traceback (most recent call last):
  File "/Users/sammuurr/PycharmProjects/GeekShop/venv/lib/python3.9/site-packages/aiogram/dispatcher/dispatcher.py", line 415, in _process_polling_updates
    for responses in itertools.chain.from_iterable(await self.process_updates(updates, fast)):
  File "/Users/sammuurr/PycharmProjects/GeekShop/venv/lib/python3.9/site-packages/aiogram/dispatcher/dispatcher.py", line 235, in process_updates
    return await asyncio.gather(*tasks)
  File "/Users/sammuurr/PycharmProjects/GeekShop/venv/lib/python3.9/site-packages/aiogram/dispatcher/handler.py", line 116, in notify
    response = await handler_obj.handler(*args, **partial_data)
  File "/Users/sammuurr/PycharmProjects/GeekShop/venv/lib/python3.9/site-packages/aiogram/dispatcher/dispatcher.py", line 256, in process_update
    return await self.message_handlers.notify(update.message)
  File "/Users/sammuurr/PycharmProjects/GeekShop/venv/lib/python3.9/site-packages/aiogram/dispatcher/handler.py", line 116, in notify
    response = await handler_obj.handler(*args, **partial_data)
  File "/Users/sammuurr/PycharmProjects/GeekShop/handlers/inline_handlers/admin_menu/admin_menu_admins.py", line 56, in enter_add_newadmin
    for admin in getUsers(is_admins=True)[0]:
IndexError: list index out of range
[2022-06-21 01:56:58,448] - [WARNING] -->  Goodbye!
[2022-06-21 01:57:06,058] - [ERROR] -->  Task exception was never retrieved
future: <Task finished name='Task-7' coro=<Dispatcher._process_polling_updates() done, defined at /Users/sammuurr/PycharmProjects/GeekShop/venv/lib/python3.9/site-packages/aiogram/dispatcher/dispatcher.py:407> exception=IndexError('list index out of range')>
Traceback (most recent call last):
  File "/Users/sammuurr/PycharmProjects/GeekShop/venv/lib/python3.9/site-packages/aiogram/dispatcher/dispatcher.py", line 415, in _process_polling_updates
    for responses in itertools.chain.from_iterable(await self.process_updates(updates, fast)):
  File "/Users/sammuurr/PycharmProjects/GeekShop/venv/lib/python3.9/site-packages/aiogram/dispatcher/dispatcher.py", line 235, in process_updates
    return await asyncio.gather(*tasks)
  File "/Users/sammuurr/PycharmProjects/GeekShop/venv/lib/python3.9/site-packages/aiogram/dispatcher/handler.py", line 116, in notify
    response = await handler_obj.handler(*args, **partial_data)
  File "/Users/sammuurr/PycharmProjects/GeekShop/venv/lib/python3.9/site-packages/aiogram/dispatcher/dispatcher.py", line 256, in process_update
    return await self.message_handlers.notify(update.message)
  File "/Users/sammuurr/PycharmProjects/GeekShop/venv/lib/python3.9/site-packages/aiogram/dispatcher/handler.py", line 116, in notify
    response = await handler_obj.handler(*args, **partial_data)
  File "/Users/sammuurr/PycharmProjects/GeekShop/handlers/command_handlers/admin.py", line 13, in process_admin_command
    if message.from_user.id in admins[0]:
IndexError: list index out of range
[2022-06-21 01:57:08,661] - [ERROR] -->  Task exception was never retrieved
future: <Task finished name='Task-10' coro=<Dispatcher._process_polling_updates() done, defined at /Users/sammuurr/PycharmProjects/GeekShop/venv/lib/python3.9/site-packages/aiogram/dispatcher/dispatcher.py:407> exception=IndexError('list index out of range')>
Traceback (most recent call last):
  File "/Users/sammuurr/PycharmProjects/GeekShop/venv/lib/python3.9/site-packages/aiogram/dispatcher/dispatcher.py", line 415, in _process_polling_updates
    for responses in itertools.chain.from_iterable(await self.process_updates(updates, fast)):
  File "/Users/sammuurr/PycharmProjects/GeekShop/venv/lib/python3.9/site-packages/aiogram/dispatcher/dispatcher.py", line 235, in process_updates
    return await asyncio.gather(*tasks)
  File "/Users/sammuurr/PycharmProjects/GeekShop/venv/lib/python3.9/site-packages/aiogram/dispatcher/handler.py", line 116, in notify
    response = await handler_obj.handler(*args, **partial_data)
  File "/Users/sammuurr/PycharmProjects/GeekShop/venv/lib/python3.9/site-packages/aiogram/dispatcher/dispatcher.py", line 256, in process_update
    return await self.message_handlers.notify(update.message)
  File "/Users/sammuurr/PycharmProjects/GeekShop/venv/lib/python3.9/site-packages/aiogram/dispatcher/handler.py", line 116, in notify
    response = await handler_obj.handler(*args, **partial_data)
  File "/Users/sammuurr/PycharmProjects/GeekShop/handlers/command_handlers/admin.py", line 13, in process_admin_command
    if message.from_user.id in admins[0]:
IndexError: list index out of range
[2022-06-21 01:57:29,243] - [WARNING] -->  Goodbye!
[2022-06-21 01:57:33,684] - [ERROR] -->  Task exception was never retrieved
future: <Task finished name='Task-7' coro=<Dispatcher._process_polling_updates() done, defined at /Users/sammuurr/PycharmProjects/GeekShop/venv/lib/python3.9/site-packages/aiogram/dispatcher/dispatcher.py:407> exception=IndexError('list index out of range')>
Traceback (most recent call last):
  File "/Users/sammuurr/PycharmProjects/GeekShop/venv/lib/python3.9/site-packages/aiogram/dispatcher/dispatcher.py", line 415, in _process_polling_updates
    for responses in itertools.chain.from_iterable(await self.process_updates(updates, fast)):
  File "/Users/sammuurr/PycharmProjects/GeekShop/venv/lib/python3.9/site-packages/aiogram/dispatcher/dispatcher.py", line 235, in process_updates
    return await asyncio.gather(*tasks)
  File "/Users/sammuurr/PycharmProjects/GeekShop/venv/lib/python3.9/site-packages/aiogram/dispatcher/handler.py", line 116, in notify
    response = await handler_obj.handler(*args, **partial_data)
  File "/Users/sammuurr/PycharmProjects/GeekShop/venv/lib/python3.9/site-packages/aiogram/dispatcher/dispatcher.py", line 256, in process_update
    return await self.message_handlers.notify(update.message)
  File "/Users/sammuurr/PycharmProjects/GeekShop/venv/lib/python3.9/site-packages/aiogram/dispatcher/handler.py", line 116, in notify
    response = await handler_obj.handler(*args, **partial_data)
  File "/Users/sammuurr/PycharmProjects/GeekShop/handlers/command_handlers/admin.py", line 13, in process_admin_command
    if message.from_user.id in admins[0]:
IndexError: list index out of range
[2022-06-21 01:58:20,433] - [WARNING] -->  Goodbye!
[2022-06-21 01:58:23,832] - [ERROR] -->  Task exception was never retrieved
future: <Task finished name='Task-7' coro=<Dispatcher._process_polling_updates() done, defined at /Users/sammuurr/PycharmProjects/GeekShop/venv/lib/python3.9/site-packages/aiogram/dispatcher/dispatcher.py:407> exception=IndexError('list index out of range')>
Traceback (most recent call last):
  File "/Users/sammuurr/PycharmProjects/GeekShop/venv/lib/python3.9/site-packages/aiogram/dispatcher/dispatcher.py", line 415, in _process_polling_updates
    for responses in itertools.chain.from_iterable(await self.process_updates(updates, fast)):
  File "/Users/sammuurr/PycharmProjects/GeekShop/venv/lib/python3.9/site-packages/aiogram/dispatcher/dispatcher.py", line 235, in process_updates
    return await asyncio.gather(*tasks)
  File "/Users/sammuurr/PycharmProjects/GeekShop/venv/lib/python3.9/site-packages/aiogram/dispatcher/handler.py", line 116, in notify
    response = await handler_obj.handler(*args, **partial_data)
  File "/Users/sammuurr/PycharmProjects/GeekShop/venv/lib/python3.9/site-packages/aiogram/dispatcher/dispatcher.py", line 256, in process_update
    return await self.message_handlers.notify(update.message)
  File "/Users/sammuurr/PycharmProjects/GeekShop/venv/lib/python3.9/site-packages/aiogram/dispatcher/handler.py", line 116, in notify
    response = await handler_obj.handler(*args, **partial_data)
  File "/Users/sammuurr/PycharmProjects/GeekShop/handlers/command_handlers/admin.py", line 15, in process_admin_command
    if message.from_user.id in admins[0]:
IndexError: list index out of range
[2022-06-21 02:00:39,895] - [ERROR] -->  Task exception was never retrieved
future: <Task finished name='Task-31' coro=<Dispatcher._process_polling_updates() done, defined at /Users/sammuurr/PycharmProjects/GeekShop/venv/lib/python3.9/site-packages/aiogram/dispatcher/dispatcher.py:407> exception=IndexError('list index out of range')>
Traceback (most recent call last):
  File "/Users/sammuurr/PycharmProjects/GeekShop/handlers/inline_handlers/admin_menu/admin_menu_admins.py", line 35, in enter_add_newadmin
    await bot.send_message(
TypeError: send_message() got an unexpected keyword argument 'id'

During handling of the above exception, another exception occurred:

Traceback (most recent call last):
  File "/Users/sammuurr/PycharmProjects/GeekShop/venv/lib/python3.9/site-packages/aiogram/dispatcher/dispatcher.py", line 415, in _process_polling_updates
    for responses in itertools.chain.from_iterable(await self.process_updates(updates, fast)):
  File "/Users/sammuurr/PycharmProjects/GeekShop/venv/lib/python3.9/site-packages/aiogram/dispatcher/dispatcher.py", line 235, in process_updates
    return await asyncio.gather(*tasks)
  File "/Users/sammuurr/PycharmProjects/GeekShop/venv/lib/python3.9/site-packages/aiogram/dispatcher/handler.py", line 116, in notify
    response = await handler_obj.handler(*args, **partial_data)
  File "/Users/sammuurr/PycharmProjects/GeekShop/venv/lib/python3.9/site-packages/aiogram/dispatcher/dispatcher.py", line 256, in process_update
    return await self.message_handlers.notify(update.message)
  File "/Users/sammuurr/PycharmProjects/GeekShop/venv/lib/python3.9/site-packages/aiogram/dispatcher/handler.py", line 116, in notify
    response = await handler_obj.handler(*args, **partial_data)
  File "/Users/sammuurr/PycharmProjects/GeekShop/handlers/inline_handlers/admin_menu/admin_menu_admins.py", line 56, in enter_add_newadmin
    for admin in getUsers(is_admins=True)[0]:
IndexError: list index out of range
[2022-06-21 02:02:37,272] - [ERROR] -->  Task exception was never retrieved
future: <Task finished name='Task-40' coro=<Dispatcher._process_polling_updates() done, defined at /Users/sammuurr/PycharmProjects/GeekShop/venv/lib/python3.9/site-packages/aiogram/dispatcher/dispatcher.py:407> exception=IndexError('list index out of range')>
Traceback (most recent call last):
  File "/Users/sammuurr/PycharmProjects/GeekShop/venv/lib/python3.9/site-packages/aiogram/dispatcher/dispatcher.py", line 415, in _process_polling_updates
    for responses in itertools.chain.from_iterable(await self.process_updates(updates, fast)):
  File "/Users/sammuurr/PycharmProjects/GeekShop/venv/lib/python3.9/site-packages/aiogram/dispatcher/dispatcher.py", line 235, in process_updates
    return await asyncio.gather(*tasks)
  File "/Users/sammuurr/PycharmProjects/GeekShop/venv/lib/python3.9/site-packages/aiogram/dispatcher/handler.py", line 116, in notify
    response = await handler_obj.handler(*args, **partial_data)
  File "/Users/sammuurr/PycharmProjects/GeekShop/venv/lib/python3.9/site-packages/aiogram/dispatcher/dispatcher.py", line 256, in process_update
    return await self.message_handlers.notify(update.message)
  File "/Users/sammuurr/PycharmProjects/GeekShop/venv/lib/python3.9/site-packages/aiogram/dispatcher/handler.py", line 116, in notify
    response = await handler_obj.handler(*args, **partial_data)
  File "/Users/sammuurr/PycharmProjects/GeekShop/handlers/command_handlers/admin.py", line 15, in process_admin_command
    "Открыл <b>панель администратора</b>", reply_markup=admin_panel_keyboard
IndexError: list index out of range
[2022-06-21 02:03:28,180] - [WARNING] -->  Goodbye!
[2022-06-21 02:03:54,987] - [ERROR] -->  Task exception was never retrieved
future: <Task finished name='Task-12' coro=<Dispatcher._process_polling_updates() done, defined at /Users/sammuurr/PycharmProjects/GeekShop/venv/lib/python3.9/site-packages/aiogram/dispatcher/dispatcher.py:407> exception=IndexError('list index out of range')>
Traceback (most recent call last):
  File "/Users/sammuurr/PycharmProjects/GeekShop/handlers/inline_handlers/admin_menu/admin_menu_admins.py", line 35, in enter_add_newadmin
    await bot.send_message(
TypeError: send_message() got an unexpected keyword argument 'id'

During handling of the above exception, another exception occurred:

Traceback (most recent call last):
  File "/Users/sammuurr/PycharmProjects/GeekShop/venv/lib/python3.9/site-packages/aiogram/dispatcher/dispatcher.py", line 415, in _process_polling_updates
    for responses in itertools.chain.from_iterable(await self.process_updates(updates, fast)):
  File "/Users/sammuurr/PycharmProjects/GeekShop/venv/lib/python3.9/site-packages/aiogram/dispatcher/dispatcher.py", line 235, in process_updates
    return await asyncio.gather(*tasks)
  File "/Users/sammuurr/PycharmProjects/GeekShop/venv/lib/python3.9/site-packages/aiogram/dispatcher/handler.py", line 116, in notify
    response = await handler_obj.handler(*args, **partial_data)
  File "/Users/sammuurr/PycharmProjects/GeekShop/venv/lib/python3.9/site-packages/aiogram/dispatcher/dispatcher.py", line 256, in process_update
    return await self.message_handlers.notify(update.message)
  File "/Users/sammuurr/PycharmProjects/GeekShop/venv/lib/python3.9/site-packages/aiogram/dispatcher/handler.py", line 116, in notify
    response = await handler_obj.handler(*args, **partial_data)
  File "/Users/sammuurr/PycharmProjects/GeekShop/handlers/inline_handlers/admin_menu/admin_menu_admins.py", line 56, in enter_add_newadmin
    for admin in getUsers(is_admins=True)[0]:
IndexError: list index out of range
[2022-06-21 02:07:00,827] - [ERROR] -->  Task exception was never retrieved
future: <Task finished name='Task-29' coro=<Dispatcher._process_polling_updates() done, defined at /Users/sammuurr/PycharmProjects/GeekShop/venv/lib/python3.9/site-packages/aiogram/dispatcher/dispatcher.py:407> exception=IndexError('list index out of range')>
Traceback (most recent call last):
  File "/Users/sammuurr/PycharmProjects/GeekShop/handlers/inline_handlers/admin_menu/admin_menu_admins.py", line 35, in enter_add_newadmin
    await bot.send_message(
TypeError: send_message() got an unexpected keyword argument 'id'

During handling of the above exception, another exception occurred:

Traceback (most recent call last):
  File "/Users/sammuurr/PycharmProjects/GeekShop/venv/lib/python3.9/site-packages/aiogram/dispatcher/dispatcher.py", line 415, in _process_polling_updates
    for responses in itertools.chain.from_iterable(await self.process_updates(updates, fast)):
  File "/Users/sammuurr/PycharmProjects/GeekShop/venv/lib/python3.9/site-packages/aiogram/dispatcher/dispatcher.py", line 235, in process_updates
    return await asyncio.gather(*tasks)
  File "/Users/sammuurr/PycharmProjects/GeekShop/venv/lib/python3.9/site-packages/aiogram/dispatcher/handler.py", line 116, in notify
    response = await handler_obj.handler(*args, **partial_data)
  File "/Users/sammuurr/PycharmProjects/GeekShop/venv/lib/python3.9/site-packages/aiogram/dispatcher/dispatcher.py", line 256, in process_update
    return await self.message_handlers.notify(update.message)
  File "/Users/sammuurr/PycharmProjects/GeekShop/venv/lib/python3.9/site-packages/aiogram/dispatcher/handler.py", line 116, in notify
    response = await handler_obj.handler(*args, **partial_data)
  File "/Users/sammuurr/PycharmProjects/GeekShop/handlers/inline_handlers/admin_menu/admin_menu_admins.py", line 56, in enter_add_newadmin
    for admin in getUsers(is_admins=True)[0]:
IndexError: list index out of range
[2022-06-21 02:08:17,207] - [WARNING] -->  Goodbye!
[2022-06-21 02:09:17,138] - [WARNING] -->  Goodbye!
[2022-06-21 02:11:11,995] - [WARNING] -->  Goodbye!
[2022-06-21 02:11:58,776] - [WARNING] -->  Goodbye!
[2022-06-21 02:13:02,683] - [WARNING] -->  Goodbye!
[2022-06-21 02:14:46,394] - [WARNING] -->  Goodbye!
[2022-06-21 02:16:31,082] - [WARNING] -->  Goodbye!
[2022-06-21 09:18:55,343] - [ERROR] -->  Cause exception while getting updates.
Traceback (most recent call last):
  File "/Users/sammuurr/PycharmProjects/GeekShop/venv/lib/python3.9/site-packages/aiogram/dispatcher/dispatcher.py", line 381, in start_polling
    updates = await self.bot.get_updates(
  File "/Users/sammuurr/PycharmProjects/GeekShop/venv/lib/python3.9/site-packages/aiogram/bot/bot.py", line 110, in get_updates
    result = await self.request(api.Methods.GET_UPDATES, payload)
  File "/Users/sammuurr/PycharmProjects/GeekShop/venv/lib/python3.9/site-packages/aiogram/bot/base.py", line 231, in request
    return await api.make_request(await self.get_session(), self.server, self.__token, method, data, files,
  File "/Users/sammuurr/PycharmProjects/GeekShop/venv/lib/python3.9/site-packages/aiogram/bot/api.py", line 139, in make_request
    async with session.post(url, data=req, **kwargs) as response:
  File "/Users/sammuurr/PycharmProjects/GeekShop/venv/lib/python3.9/site-packages/aiohttp/client.py", line 1138, in __aenter__
    self._resp = await self._coro
  File "/Users/sammuurr/PycharmProjects/GeekShop/venv/lib/python3.9/site-packages/aiohttp/client.py", line 559, in _request
    await resp.start(conn)
  File "/Users/sammuurr/PycharmProjects/GeekShop/venv/lib/python3.9/site-packages/aiohttp/client_reqrep.py", line 913, in start
    self._continue = None
  File "/Users/sammuurr/PycharmProjects/GeekShop/venv/lib/python3.9/site-packages/aiohttp/helpers.py", line 721, in __exit__
    raise asyncio.TimeoutError from None
asyncio.exceptions.TimeoutError
[2022-06-21 14:46:50,118] - [ERROR] -->  Cause exception while getting updates.
Traceback (most recent call last):
  File "/Users/sammuurr/PycharmProjects/GeekShop/venv/lib/python3.9/site-packages/aiogram/dispatcher/dispatcher.py", line 381, in start_polling
    updates = await self.bot.get_updates(
  File "/Users/sammuurr/PycharmProjects/GeekShop/venv/lib/python3.9/site-packages/aiogram/bot/bot.py", line 110, in get_updates
    result = await self.request(api.Methods.GET_UPDATES, payload)
  File "/Users/sammuurr/PycharmProjects/GeekShop/venv/lib/python3.9/site-packages/aiogram/bot/base.py", line 231, in request
    return await api.make_request(await self.get_session(), self.server, self.__token, method, data, files,
  File "/Users/sammuurr/PycharmProjects/GeekShop/venv/lib/python3.9/site-packages/aiogram/bot/api.py", line 139, in make_request
    async with session.post(url, data=req, **kwargs) as response:
  File "/Users/sammuurr/PycharmProjects/GeekShop/venv/lib/python3.9/site-packages/aiohttp/client.py", line 1138, in __aenter__
    self._resp = await self._coro
  File "/Users/sammuurr/PycharmProjects/GeekShop/venv/lib/python3.9/site-packages/aiohttp/client.py", line 559, in _request
    await resp.start(conn)
  File "/Users/sammuurr/PycharmProjects/GeekShop/venv/lib/python3.9/site-packages/aiohttp/client_reqrep.py", line 913, in start
    self._continue = None
  File "/Users/sammuurr/PycharmProjects/GeekShop/venv/lib/python3.9/site-packages/aiohttp/helpers.py", line 721, in __exit__
    raise asyncio.TimeoutError from None
asyncio.exceptions.TimeoutError
[2022-06-21 18:12:59,858] - [ERROR] -->  Cause exception while getting updates.
Traceback (most recent call last):
  File "/Users/sammuurr/PycharmProjects/GeekShop/venv/lib/python3.9/site-packages/aiogram/dispatcher/dispatcher.py", line 381, in start_polling
    updates = await self.bot.get_updates(
  File "/Users/sammuurr/PycharmProjects/GeekShop/venv/lib/python3.9/site-packages/aiogram/bot/bot.py", line 110, in get_updates
    result = await self.request(api.Methods.GET_UPDATES, payload)
  File "/Users/sammuurr/PycharmProjects/GeekShop/venv/lib/python3.9/site-packages/aiogram/bot/base.py", line 231, in request
    return await api.make_request(await self.get_session(), self.server, self.__token, method, data, files,
  File "/Users/sammuurr/PycharmProjects/GeekShop/venv/lib/python3.9/site-packages/aiogram/bot/api.py", line 139, in make_request
    async with session.post(url, data=req, **kwargs) as response:
  File "/Users/sammuurr/PycharmProjects/GeekShop/venv/lib/python3.9/site-packages/aiohttp/client.py", line 1138, in __aenter__
    self._resp = await self._coro
  File "/Users/sammuurr/PycharmProjects/GeekShop/venv/lib/python3.9/site-packages/aiohttp/client.py", line 559, in _request
    await resp.start(conn)
  File "/Users/sammuurr/PycharmProjects/GeekShop/venv/lib/python3.9/site-packages/aiohttp/client_reqrep.py", line 913, in start
    self._continue = None
  File "/Users/sammuurr/PycharmProjects/GeekShop/venv/lib/python3.9/site-packages/aiohttp/helpers.py", line 721, in __exit__
    raise asyncio.TimeoutError from None
asyncio.exceptions.TimeoutError
[2022-06-22 01:48:49,364] - [ERROR] -->  Cause exception while getting updates.
Traceback (most recent call last):
  File "/Users/sammuurr/PycharmProjects/GeekShop/venv/lib/python3.9/site-packages/aiogram/dispatcher/dispatcher.py", line 381, in start_polling
    updates = await self.bot.get_updates(
  File "/Users/sammuurr/PycharmProjects/GeekShop/venv/lib/python3.9/site-packages/aiogram/bot/bot.py", line 110, in get_updates
    result = await self.request(api.Methods.GET_UPDATES, payload)
  File "/Users/sammuurr/PycharmProjects/GeekShop/venv/lib/python3.9/site-packages/aiogram/bot/base.py", line 231, in request
    return await api.make_request(await self.get_session(), self.server, self.__token, method, data, files,
  File "/Users/sammuurr/PycharmProjects/GeekShop/venv/lib/python3.9/site-packages/aiogram/bot/api.py", line 139, in make_request
    async with session.post(url, data=req, **kwargs) as response:
  File "/Users/sammuurr/PycharmProjects/GeekShop/venv/lib/python3.9/site-packages/aiohttp/client.py", line 1138, in __aenter__
    self._resp = await self._coro
  File "/Users/sammuurr/PycharmProjects/GeekShop/venv/lib/python3.9/site-packages/aiohttp/client.py", line 559, in _request
    await resp.start(conn)
  File "/Users/sammuurr/PycharmProjects/GeekShop/venv/lib/python3.9/site-packages/aiohttp/client_reqrep.py", line 913, in start
    self._continue = None
  File "/Users/sammuurr/PycharmProjects/GeekShop/venv/lib/python3.9/site-packages/aiohttp/helpers.py", line 721, in __exit__
    raise asyncio.TimeoutError from None
asyncio.exceptions.TimeoutError
[2022-06-22 03:44:03,004] - [ERROR] -->  Cause exception while getting updates.
Traceback (most recent call last):
  File "/Users/sammuurr/PycharmProjects/GeekShop/venv/lib/python3.9/site-packages/aiogram/dispatcher/dispatcher.py", line 381, in start_polling
    updates = await self.bot.get_updates(
  File "/Users/sammuurr/PycharmProjects/GeekShop/venv/lib/python3.9/site-packages/aiogram/bot/bot.py", line 110, in get_updates
    result = await self.request(api.Methods.GET_UPDATES, payload)
  File "/Users/sammuurr/PycharmProjects/GeekShop/venv/lib/python3.9/site-packages/aiogram/bot/base.py", line 231, in request
    return await api.make_request(await self.get_session(), self.server, self.__token, method, data, files,
  File "/Users/sammuurr/PycharmProjects/GeekShop/venv/lib/python3.9/site-packages/aiogram/bot/api.py", line 139, in make_request
    async with session.post(url, data=req, **kwargs) as response:
  File "/Users/sammuurr/PycharmProjects/GeekShop/venv/lib/python3.9/site-packages/aiohttp/client.py", line 1138, in __aenter__
    self._resp = await self._coro
  File "/Users/sammuurr/PycharmProjects/GeekShop/venv/lib/python3.9/site-packages/aiohttp/client.py", line 559, in _request
    await resp.start(conn)
  File "/Users/sammuurr/PycharmProjects/GeekShop/venv/lib/python3.9/site-packages/aiohttp/client_reqrep.py", line 913, in start
    self._continue = None
  File "/Users/sammuurr/PycharmProjects/GeekShop/venv/lib/python3.9/site-packages/aiohttp/helpers.py", line 721, in __exit__
    raise asyncio.TimeoutError from None
asyncio.exceptions.TimeoutError
[2022-06-22 12:01:26,160] - [ERROR] -->  Cause exception while getting updates.
Traceback (most recent call last):
  File "/Users/sammuurr/PycharmProjects/GeekShop/venv/lib/python3.9/site-packages/aiogram/dispatcher/dispatcher.py", line 381, in start_polling
    updates = await self.bot.get_updates(
  File "/Users/sammuurr/PycharmProjects/GeekShop/venv/lib/python3.9/site-packages/aiogram/bot/bot.py", line 110, in get_updates
    result = await self.request(api.Methods.GET_UPDATES, payload)
  File "/Users/sammuurr/PycharmProjects/GeekShop/venv/lib/python3.9/site-packages/aiogram/bot/base.py", line 231, in request
    return await api.make_request(await self.get_session(), self.server, self.__token, method, data, files,
  File "/Users/sammuurr/PycharmProjects/GeekShop/venv/lib/python3.9/site-packages/aiogram/bot/api.py", line 139, in make_request
    async with session.post(url, data=req, **kwargs) as response:
  File "/Users/sammuurr/PycharmProjects/GeekShop/venv/lib/python3.9/site-packages/aiohttp/client.py", line 1138, in __aenter__
    self._resp = await self._coro
  File "/Users/sammuurr/PycharmProjects/GeekShop/venv/lib/python3.9/site-packages/aiohttp/client.py", line 559, in _request
    await resp.start(conn)
  File "/Users/sammuurr/PycharmProjects/GeekShop/venv/lib/python3.9/site-packages/aiohttp/client_reqrep.py", line 913, in start
    self._continue = None
  File "/Users/sammuurr/PycharmProjects/GeekShop/venv/lib/python3.9/site-packages/aiohttp/helpers.py", line 721, in __exit__
    raise asyncio.TimeoutError from None
asyncio.exceptions.TimeoutError
[2022-06-22 16:55:29,822] - [ERROR] -->  Cause exception while getting updates.
Traceback (most recent call last):
  File "/Users/sammuurr/PycharmProjects/GeekShop/venv/lib/python3.9/site-packages/aiogram/dispatcher/dispatcher.py", line 381, in start_polling
    updates = await self.bot.get_updates(
  File "/Users/sammuurr/PycharmProjects/GeekShop/venv/lib/python3.9/site-packages/aiogram/bot/bot.py", line 110, in get_updates
    result = await self.request(api.Methods.GET_UPDATES, payload)
  File "/Users/sammuurr/PycharmProjects/GeekShop/venv/lib/python3.9/site-packages/aiogram/bot/base.py", line 231, in request
    return await api.make_request(await self.get_session(), self.server, self.__token, method, data, files,
  File "/Users/sammuurr/PycharmProjects/GeekShop/venv/lib/python3.9/site-packages/aiogram/bot/api.py", line 139, in make_request
    async with session.post(url, data=req, **kwargs) as response:
  File "/Users/sammuurr/PycharmProjects/GeekShop/venv/lib/python3.9/site-packages/aiohttp/client.py", line 1138, in __aenter__
    self._resp = await self._coro
  File "/Users/sammuurr/PycharmProjects/GeekShop/venv/lib/python3.9/site-packages/aiohttp/client.py", line 559, in _request
    await resp.start(conn)
  File "/Users/sammuurr/PycharmProjects/GeekShop/venv/lib/python3.9/site-packages/aiohttp/client_reqrep.py", line 913, in start
    self._continue = None
  File "/Users/sammuurr/PycharmProjects/GeekShop/venv/lib/python3.9/site-packages/aiohttp/helpers.py", line 721, in __exit__
    raise asyncio.TimeoutError from None
asyncio.exceptions.TimeoutError
[2022-06-22 19:39:53,915] - [ERROR] -->  Cause exception while getting updates.
Traceback (most recent call last):
  File "/Users/sammuurr/PycharmProjects/GeekShop/venv/lib/python3.9/site-packages/aiogram/dispatcher/dispatcher.py", line 381, in start_polling
    updates = await self.bot.get_updates(
  File "/Users/sammuurr/PycharmProjects/GeekShop/venv/lib/python3.9/site-packages/aiogram/bot/bot.py", line 110, in get_updates
    result = await self.request(api.Methods.GET_UPDATES, payload)
  File "/Users/sammuurr/PycharmProjects/GeekShop/venv/lib/python3.9/site-packages/aiogram/bot/base.py", line 231, in request
    return await api.make_request(await self.get_session(), self.server, self.__token, method, data, files,
  File "/Users/sammuurr/PycharmProjects/GeekShop/venv/lib/python3.9/site-packages/aiogram/bot/api.py", line 139, in make_request
    async with session.post(url, data=req, **kwargs) as response:
  File "/Users/sammuurr/PycharmProjects/GeekShop/venv/lib/python3.9/site-packages/aiohttp/client.py", line 1138, in __aenter__
    self._resp = await self._coro
  File "/Users/sammuurr/PycharmProjects/GeekShop/venv/lib/python3.9/site-packages/aiohttp/client.py", line 559, in _request
    await resp.start(conn)
  File "/Users/sammuurr/PycharmProjects/GeekShop/venv/lib/python3.9/site-packages/aiohttp/client_reqrep.py", line 913, in start
    self._continue = None
  File "/Users/sammuurr/PycharmProjects/GeekShop/venv/lib/python3.9/site-packages/aiohttp/helpers.py", line 721, in __exit__
    raise asyncio.TimeoutError from None
asyncio.exceptions.TimeoutError
[2022-06-22 20:29:33,234] - [ERROR] -->  Cause exception while getting updates.
Traceback (most recent call last):
  File "/Users/sammuurr/PycharmProjects/GeekShop/venv/lib/python3.9/site-packages/aiogram/dispatcher/dispatcher.py", line 381, in start_polling
    updates = await self.bot.get_updates(
  File "/Users/sammuurr/PycharmProjects/GeekShop/venv/lib/python3.9/site-packages/aiogram/bot/bot.py", line 110, in get_updates
    result = await self.request(api.Methods.GET_UPDATES, payload)
  File "/Users/sammuurr/PycharmProjects/GeekShop/venv/lib/python3.9/site-packages/aiogram/bot/base.py", line 231, in request
    return await api.make_request(await self.get_session(), self.server, self.__token, method, data, files,
  File "/Users/sammuurr/PycharmProjects/GeekShop/venv/lib/python3.9/site-packages/aiogram/bot/api.py", line 139, in make_request
    async with session.post(url, data=req, **kwargs) as response:
  File "/Users/sammuurr/PycharmProjects/GeekShop/venv/lib/python3.9/site-packages/aiohttp/client.py", line 1138, in __aenter__
    self._resp = await self._coro
  File "/Users/sammuurr/PycharmProjects/GeekShop/venv/lib/python3.9/site-packages/aiohttp/client.py", line 559, in _request
    await resp.start(conn)
  File "/Users/sammuurr/PycharmProjects/GeekShop/venv/lib/python3.9/site-packages/aiohttp/client_reqrep.py", line 913, in start
    self._continue = None
  File "/Users/sammuurr/PycharmProjects/GeekShop/venv/lib/python3.9/site-packages/aiohttp/helpers.py", line 721, in __exit__
    raise asyncio.TimeoutError from None
asyncio.exceptions.TimeoutError
[2022-06-22 23:56:09,941] - [ERROR] -->  Cause exception while getting updates.
Traceback (most recent call last):
  File "/Users/sammuurr/PycharmProjects/GeekShop/venv/lib/python3.9/site-packages/aiogram/dispatcher/dispatcher.py", line 381, in start_polling
    updates = await self.bot.get_updates(
  File "/Users/sammuurr/PycharmProjects/GeekShop/venv/lib/python3.9/site-packages/aiogram/bot/bot.py", line 110, in get_updates
    result = await self.request(api.Methods.GET_UPDATES, payload)
  File "/Users/sammuurr/PycharmProjects/GeekShop/venv/lib/python3.9/site-packages/aiogram/bot/base.py", line 231, in request
    return await api.make_request(await self.get_session(), self.server, self.__token, method, data, files,
  File "/Users/sammuurr/PycharmProjects/GeekShop/venv/lib/python3.9/site-packages/aiogram/bot/api.py", line 139, in make_request
    async with session.post(url, data=req, **kwargs) as response:
  File "/Users/sammuurr/PycharmProjects/GeekShop/venv/lib/python3.9/site-packages/aiohttp/client.py", line 1138, in __aenter__
    self._resp = await self._coro
  File "/Users/sammuurr/PycharmProjects/GeekShop/venv/lib/python3.9/site-packages/aiohttp/client.py", line 559, in _request
    await resp.start(conn)
  File "/Users/sammuurr/PycharmProjects/GeekShop/venv/lib/python3.9/site-packages/aiohttp/client_reqrep.py", line 913, in start
    self._continue = None
  File "/Users/sammuurr/PycharmProjects/GeekShop/venv/lib/python3.9/site-packages/aiohttp/helpers.py", line 721, in __exit__
    raise asyncio.TimeoutError from None
asyncio.exceptions.TimeoutError
[2022-06-23 01:22:59,832] - [ERROR] -->  Cause exception while getting updates.
Traceback (most recent call last):
  File "/Users/sammuurr/PycharmProjects/GeekShop/venv/lib/python3.9/site-packages/aiogram/dispatcher/dispatcher.py", line 381, in start_polling
    updates = await self.bot.get_updates(
  File "/Users/sammuurr/PycharmProjects/GeekShop/venv/lib/python3.9/site-packages/aiogram/bot/bot.py", line 110, in get_updates
    result = await self.request(api.Methods.GET_UPDATES, payload)
  File "/Users/sammuurr/PycharmProjects/GeekShop/venv/lib/python3.9/site-packages/aiogram/bot/base.py", line 231, in request
    return await api.make_request(await self.get_session(), self.server, self.__token, method, data, files,
  File "/Users/sammuurr/PycharmProjects/GeekShop/venv/lib/python3.9/site-packages/aiogram/bot/api.py", line 139, in make_request
    async with session.post(url, data=req, **kwargs) as response:
  File "/Users/sammuurr/PycharmProjects/GeekShop/venv/lib/python3.9/site-packages/aiohttp/client.py", line 1138, in __aenter__
    self._resp = await self._coro
  File "/Users/sammuurr/PycharmProjects/GeekShop/venv/lib/python3.9/site-packages/aiohttp/client.py", line 559, in _request
    await resp.start(conn)
  File "/Users/sammuurr/PycharmProjects/GeekShop/venv/lib/python3.9/site-packages/aiohttp/client_reqrep.py", line 913, in start
    self._continue = None
  File "/Users/sammuurr/PycharmProjects/GeekShop/venv/lib/python3.9/site-packages/aiohttp/helpers.py", line 721, in __exit__
    raise asyncio.TimeoutError from None
asyncio.exceptions.TimeoutError
[2022-06-23 08:35:49,031] - [ERROR] -->  Cause exception while getting updates.
Traceback (most recent call last):
  File "/Users/sammuurr/PycharmProjects/GeekShop/venv/lib/python3.9/site-packages/aiogram/dispatcher/dispatcher.py", line 381, in start_polling
    updates = await self.bot.get_updates(
  File "/Users/sammuurr/PycharmProjects/GeekShop/venv/lib/python3.9/site-packages/aiogram/bot/bot.py", line 110, in get_updates
    result = await self.request(api.Methods.GET_UPDATES, payload)
  File "/Users/sammuurr/PycharmProjects/GeekShop/venv/lib/python3.9/site-packages/aiogram/bot/base.py", line 231, in request
    return await api.make_request(await self.get_session(), self.server, self.__token, method, data, files,
  File "/Users/sammuurr/PycharmProjects/GeekShop/venv/lib/python3.9/site-packages/aiogram/bot/api.py", line 139, in make_request
    async with session.post(url, data=req, **kwargs) as response:
  File "/Users/sammuurr/PycharmProjects/GeekShop/venv/lib/python3.9/site-packages/aiohttp/client.py", line 1138, in __aenter__
    self._resp = await self._coro
  File "/Users/sammuurr/PycharmProjects/GeekShop/venv/lib/python3.9/site-packages/aiohttp/client.py", line 559, in _request
    await resp.start(conn)
  File "/Users/sammuurr/PycharmProjects/GeekShop/venv/lib/python3.9/site-packages/aiohttp/client_reqrep.py", line 913, in start
    self._continue = None
  File "/Users/sammuurr/PycharmProjects/GeekShop/venv/lib/python3.9/site-packages/aiohttp/helpers.py", line 721, in __exit__
    raise asyncio.TimeoutError from None
asyncio.exceptions.TimeoutError
[2022-06-23 13:51:10,924] - [ERROR] -->  Cause exception while getting updates.
Traceback (most recent call last):
  File "/Users/sammuurr/PycharmProjects/GeekShop/venv/lib/python3.9/site-packages/aiogram/dispatcher/dispatcher.py", line 381, in start_polling
    updates = await self.bot.get_updates(
  File "/Users/sammuurr/PycharmProjects/GeekShop/venv/lib/python3.9/site-packages/aiogram/bot/bot.py", line 110, in get_updates
    result = await self.request(api.Methods.GET_UPDATES, payload)
  File "/Users/sammuurr/PycharmProjects/GeekShop/venv/lib/python3.9/site-packages/aiogram/bot/base.py", line 231, in request
    return await api.make_request(await self.get_session(), self.server, self.__token, method, data, files,
  File "/Users/sammuurr/PycharmProjects/GeekShop/venv/lib/python3.9/site-packages/aiogram/bot/api.py", line 139, in make_request
    async with session.post(url, data=req, **kwargs) as response:
  File "/Users/sammuurr/PycharmProjects/GeekShop/venv/lib/python3.9/site-packages/aiohttp/client.py", line 1138, in __aenter__
    self._resp = await self._coro
  File "/Users/sammuurr/PycharmProjects/GeekShop/venv/lib/python3.9/site-packages/aiohttp/client.py", line 559, in _request
    await resp.start(conn)
  File "/Users/sammuurr/PycharmProjects/GeekShop/venv/lib/python3.9/site-packages/aiohttp/client_reqrep.py", line 913, in start
    self._continue = None
  File "/Users/sammuurr/PycharmProjects/GeekShop/venv/lib/python3.9/site-packages/aiohttp/helpers.py", line 721, in __exit__
    raise asyncio.TimeoutError from None
asyncio.exceptions.TimeoutError
[2022-06-23 20:10:25,405] - [ERROR] -->  Cause exception while getting updates.
Traceback (most recent call last):
  File "/Users/sammuurr/PycharmProjects/GeekShop/venv/lib/python3.9/site-packages/aiogram/dispatcher/dispatcher.py", line 381, in start_polling
    updates = await self.bot.get_updates(
  File "/Users/sammuurr/PycharmProjects/GeekShop/venv/lib/python3.9/site-packages/aiogram/bot/bot.py", line 110, in get_updates
    result = await self.request(api.Methods.GET_UPDATES, payload)
  File "/Users/sammuurr/PycharmProjects/GeekShop/venv/lib/python3.9/site-packages/aiogram/bot/base.py", line 231, in request
    return await api.make_request(await self.get_session(), self.server, self.__token, method, data, files,
  File "/Users/sammuurr/PycharmProjects/GeekShop/venv/lib/python3.9/site-packages/aiogram/bot/api.py", line 139, in make_request
    async with session.post(url, data=req, **kwargs) as response:
  File "/Users/sammuurr/PycharmProjects/GeekShop/venv/lib/python3.9/site-packages/aiohttp/client.py", line 1138, in __aenter__
    self._resp = await self._coro
  File "/Users/sammuurr/PycharmProjects/GeekShop/venv/lib/python3.9/site-packages/aiohttp/client.py", line 559, in _request
    await resp.start(conn)
  File "/Users/sammuurr/PycharmProjects/GeekShop/venv/lib/python3.9/site-packages/aiohttp/client_reqrep.py", line 913, in start
    self._continue = None
  File "/Users/sammuurr/PycharmProjects/GeekShop/venv/lib/python3.9/site-packages/aiohttp/helpers.py", line 721, in __exit__
    raise asyncio.TimeoutError from None
asyncio.exceptions.TimeoutError
[2022-06-24 00:43:54,801] - [ERROR] -->  Cause exception while getting updates.
Traceback (most recent call last):
  File "/Users/sammuurr/PycharmProjects/GeekShop/venv/lib/python3.9/site-packages/aiogram/dispatcher/dispatcher.py", line 381, in start_polling
    updates = await self.bot.get_updates(
  File "/Users/sammuurr/PycharmProjects/GeekShop/venv/lib/python3.9/site-packages/aiogram/bot/bot.py", line 110, in get_updates
    result = await self.request(api.Methods.GET_UPDATES, payload)
  File "/Users/sammuurr/PycharmProjects/GeekShop/venv/lib/python3.9/site-packages/aiogram/bot/base.py", line 231, in request
    return await api.make_request(await self.get_session(), self.server, self.__token, method, data, files,
  File "/Users/sammuurr/PycharmProjects/GeekShop/venv/lib/python3.9/site-packages/aiogram/bot/api.py", line 139, in make_request
    async with session.post(url, data=req, **kwargs) as response:
  File "/Users/sammuurr/PycharmProjects/GeekShop/venv/lib/python3.9/site-packages/aiohttp/client.py", line 1138, in __aenter__
    self._resp = await self._coro
  File "/Users/sammuurr/PycharmProjects/GeekShop/venv/lib/python3.9/site-packages/aiohttp/client.py", line 559, in _request
    await resp.start(conn)
  File "/Users/sammuurr/PycharmProjects/GeekShop/venv/lib/python3.9/site-packages/aiohttp/client_reqrep.py", line 913, in start
    self._continue = None
  File "/Users/sammuurr/PycharmProjects/GeekShop/venv/lib/python3.9/site-packages/aiohttp/helpers.py", line 721, in __exit__
    raise asyncio.TimeoutError from None
asyncio.exceptions.TimeoutError
[2022-06-24 06:27:47,767] - [ERROR] -->  Cause exception while getting updates.
Traceback (most recent call last):
  File "/Users/sammuurr/PycharmProjects/GeekShop/venv/lib/python3.9/site-packages/aiogram/dispatcher/dispatcher.py", line 381, in start_polling
    updates = await self.bot.get_updates(
  File "/Users/sammuurr/PycharmProjects/GeekShop/venv/lib/python3.9/site-packages/aiogram/bot/bot.py", line 110, in get_updates
    result = await self.request(api.Methods.GET_UPDATES, payload)
  File "/Users/sammuurr/PycharmProjects/GeekShop/venv/lib/python3.9/site-packages/aiogram/bot/base.py", line 231, in request
    return await api.make_request(await self.get_session(), self.server, self.__token, method, data, files,
  File "/Users/sammuurr/PycharmProjects/GeekShop/venv/lib/python3.9/site-packages/aiogram/bot/api.py", line 139, in make_request
    async with session.post(url, data=req, **kwargs) as response:
  File "/Users/sammuurr/PycharmProjects/GeekShop/venv/lib/python3.9/site-packages/aiohttp/client.py", line 1138, in __aenter__
    self._resp = await self._coro
  File "/Users/sammuurr/PycharmProjects/GeekShop/venv/lib/python3.9/site-packages/aiohttp/client.py", line 559, in _request
    await resp.start(conn)
  File "/Users/sammuurr/PycharmProjects/GeekShop/venv/lib/python3.9/site-packages/aiohttp/client_reqrep.py", line 913, in start
    self._continue = None
  File "/Users/sammuurr/PycharmProjects/GeekShop/venv/lib/python3.9/site-packages/aiohttp/helpers.py", line 721, in __exit__
    raise asyncio.TimeoutError from None
asyncio.exceptions.TimeoutError
[2022-06-24 11:58:32,115] - [ERROR] -->  Cause exception while getting updates.
Traceback (most recent call last):
  File "/Users/sammuurr/PycharmProjects/GeekShop/venv/lib/python3.9/site-packages/aiogram/dispatcher/dispatcher.py", line 381, in start_polling
    updates = await self.bot.get_updates(
  File "/Users/sammuurr/PycharmProjects/GeekShop/venv/lib/python3.9/site-packages/aiogram/bot/bot.py", line 110, in get_updates
    result = await self.request(api.Methods.GET_UPDATES, payload)
  File "/Users/sammuurr/PycharmProjects/GeekShop/venv/lib/python3.9/site-packages/aiogram/bot/base.py", line 231, in request
    return await api.make_request(await self.get_session(), self.server, self.__token, method, data, files,
  File "/Users/sammuurr/PycharmProjects/GeekShop/venv/lib/python3.9/site-packages/aiogram/bot/api.py", line 139, in make_request
    async with session.post(url, data=req, **kwargs) as response:
  File "/Users/sammuurr/PycharmProjects/GeekShop/venv/lib/python3.9/site-packages/aiohttp/client.py", line 1138, in __aenter__
    self._resp = await self._coro
  File "/Users/sammuurr/PycharmProjects/GeekShop/venv/lib/python3.9/site-packages/aiohttp/client.py", line 559, in _request
    await resp.start(conn)
  File "/Users/sammuurr/PycharmProjects/GeekShop/venv/lib/python3.9/site-packages/aiohttp/client_reqrep.py", line 913, in start
    self._continue = None
  File "/Users/sammuurr/PycharmProjects/GeekShop/venv/lib/python3.9/site-packages/aiohttp/helpers.py", line 721, in __exit__
    raise asyncio.TimeoutError from None
asyncio.exceptions.TimeoutError
[2022-06-24 12:35:47,117] - [ERROR] -->  Cause exception while getting updates.
Traceback (most recent call last):
  File "/Users/sammuurr/PycharmProjects/GeekShop/venv/lib/python3.9/site-packages/aiogram/dispatcher/dispatcher.py", line 381, in start_polling
    updates = await self.bot.get_updates(
  File "/Users/sammuurr/PycharmProjects/GeekShop/venv/lib/python3.9/site-packages/aiogram/bot/bot.py", line 110, in get_updates
    result = await self.request(api.Methods.GET_UPDATES, payload)
  File "/Users/sammuurr/PycharmProjects/GeekShop/venv/lib/python3.9/site-packages/aiogram/bot/base.py", line 231, in request
    return await api.make_request(await self.get_session(), self.server, self.__token, method, data, files,
  File "/Users/sammuurr/PycharmProjects/GeekShop/venv/lib/python3.9/site-packages/aiogram/bot/api.py", line 139, in make_request
    async with session.post(url, data=req, **kwargs) as response:
  File "/Users/sammuurr/PycharmProjects/GeekShop/venv/lib/python3.9/site-packages/aiohttp/client.py", line 1138, in __aenter__
    self._resp = await self._coro
  File "/Users/sammuurr/PycharmProjects/GeekShop/venv/lib/python3.9/site-packages/aiohttp/client.py", line 559, in _request
    await resp.start(conn)
  File "/Users/sammuurr/PycharmProjects/GeekShop/venv/lib/python3.9/site-packages/aiohttp/client_reqrep.py", line 913, in start
    self._continue = None
  File "/Users/sammuurr/PycharmProjects/GeekShop/venv/lib/python3.9/site-packages/aiohttp/helpers.py", line 721, in __exit__
    raise asyncio.TimeoutError from None
asyncio.exceptions.TimeoutError
[2022-06-24 15:09:16,813] - [ERROR] -->  Cause exception while getting updates.
Traceback (most recent call last):
  File "/Users/sammuurr/PycharmProjects/GeekShop/venv/lib/python3.9/site-packages/aiogram/dispatcher/dispatcher.py", line 381, in start_polling
    updates = await self.bot.get_updates(
  File "/Users/sammuurr/PycharmProjects/GeekShop/venv/lib/python3.9/site-packages/aiogram/bot/bot.py", line 110, in get_updates
    result = await self.request(api.Methods.GET_UPDATES, payload)
  File "/Users/sammuurr/PycharmProjects/GeekShop/venv/lib/python3.9/site-packages/aiogram/bot/base.py", line 231, in request
    return await api.make_request(await self.get_session(), self.server, self.__token, method, data, files,
  File "/Users/sammuurr/PycharmProjects/GeekShop/venv/lib/python3.9/site-packages/aiogram/bot/api.py", line 139, in make_request
    async with session.post(url, data=req, **kwargs) as response:
  File "/Users/sammuurr/PycharmProjects/GeekShop/venv/lib/python3.9/site-packages/aiohttp/client.py", line 1138, in __aenter__
    self._resp = await self._coro
  File "/Users/sammuurr/PycharmProjects/GeekShop/venv/lib/python3.9/site-packages/aiohttp/client.py", line 559, in _request
    await resp.start(conn)
  File "/Users/sammuurr/PycharmProjects/GeekShop/venv/lib/python3.9/site-packages/aiohttp/client_reqrep.py", line 913, in start
    self._continue = None
  File "/Users/sammuurr/PycharmProjects/GeekShop/venv/lib/python3.9/site-packages/aiohttp/helpers.py", line 721, in __exit__
    raise asyncio.TimeoutError from None
asyncio.exceptions.TimeoutError
[2022-06-24 19:43:00,051] - [ERROR] -->  Cause exception while getting updates.
Traceback (most recent call last):
  File "/Users/sammuurr/PycharmProjects/GeekShop/venv/lib/python3.9/site-packages/aiogram/dispatcher/dispatcher.py", line 381, in start_polling
    updates = await self.bot.get_updates(
  File "/Users/sammuurr/PycharmProjects/GeekShop/venv/lib/python3.9/site-packages/aiogram/bot/bot.py", line 110, in get_updates
    result = await self.request(api.Methods.GET_UPDATES, payload)
  File "/Users/sammuurr/PycharmProjects/GeekShop/venv/lib/python3.9/site-packages/aiogram/bot/base.py", line 231, in request
    return await api.make_request(await self.get_session(), self.server, self.__token, method, data, files,
  File "/Users/sammuurr/PycharmProjects/GeekShop/venv/lib/python3.9/site-packages/aiogram/bot/api.py", line 139, in make_request
    async with session.post(url, data=req, **kwargs) as response:
  File "/Users/sammuurr/PycharmProjects/GeekShop/venv/lib/python3.9/site-packages/aiohttp/client.py", line 1138, in __aenter__
    self._resp = await self._coro
  File "/Users/sammuurr/PycharmProjects/GeekShop/venv/lib/python3.9/site-packages/aiohttp/client.py", line 559, in _request
    await resp.start(conn)
  File "/Users/sammuurr/PycharmProjects/GeekShop/venv/lib/python3.9/site-packages/aiohttp/client_reqrep.py", line 913, in start
    self._continue = None
  File "/Users/sammuurr/PycharmProjects/GeekShop/venv/lib/python3.9/site-packages/aiohttp/helpers.py", line 721, in __exit__
    raise asyncio.TimeoutError from None
asyncio.exceptions.TimeoutError
[2022-06-25 03:14:48,059] - [ERROR] -->  Cause exception while getting updates.
Traceback (most recent call last):
  File "/Users/sammuurr/PycharmProjects/GeekShop/venv/lib/python3.9/site-packages/aiogram/dispatcher/dispatcher.py", line 381, in start_polling
    updates = await self.bot.get_updates(
  File "/Users/sammuurr/PycharmProjects/GeekShop/venv/lib/python3.9/site-packages/aiogram/bot/bot.py", line 110, in get_updates
    result = await self.request(api.Methods.GET_UPDATES, payload)
  File "/Users/sammuurr/PycharmProjects/GeekShop/venv/lib/python3.9/site-packages/aiogram/bot/base.py", line 231, in request
    return await api.make_request(await self.get_session(), self.server, self.__token, method, data, files,
  File "/Users/sammuurr/PycharmProjects/GeekShop/venv/lib/python3.9/site-packages/aiogram/bot/api.py", line 139, in make_request
    async with session.post(url, data=req, **kwargs) as response:
  File "/Users/sammuurr/PycharmProjects/GeekShop/venv/lib/python3.9/site-packages/aiohttp/client.py", line 1138, in __aenter__
    self._resp = await self._coro
  File "/Users/sammuurr/PycharmProjects/GeekShop/venv/lib/python3.9/site-packages/aiohttp/client.py", line 559, in _request
    await resp.start(conn)
  File "/Users/sammuurr/PycharmProjects/GeekShop/venv/lib/python3.9/site-packages/aiohttp/client_reqrep.py", line 913, in start
    self._continue = None
  File "/Users/sammuurr/PycharmProjects/GeekShop/venv/lib/python3.9/site-packages/aiohttp/helpers.py", line 721, in __exit__
    raise asyncio.TimeoutError from None
asyncio.exceptions.TimeoutError
[2022-06-25 12:53:44,365] - [ERROR] -->  Cause exception while getting updates.
Traceback (most recent call last):
  File "/Users/sammuurr/PycharmProjects/GeekShop/venv/lib/python3.9/site-packages/aiogram/dispatcher/dispatcher.py", line 381, in start_polling
    updates = await self.bot.get_updates(
  File "/Users/sammuurr/PycharmProjects/GeekShop/venv/lib/python3.9/site-packages/aiogram/bot/bot.py", line 110, in get_updates
    result = await self.request(api.Methods.GET_UPDATES, payload)
  File "/Users/sammuurr/PycharmProjects/GeekShop/venv/lib/python3.9/site-packages/aiogram/bot/base.py", line 231, in request
    return await api.make_request(await self.get_session(), self.server, self.__token, method, data, files,
  File "/Users/sammuurr/PycharmProjects/GeekShop/venv/lib/python3.9/site-packages/aiogram/bot/api.py", line 139, in make_request
    async with session.post(url, data=req, **kwargs) as response:
  File "/Users/sammuurr/PycharmProjects/GeekShop/venv/lib/python3.9/site-packages/aiohttp/client.py", line 1138, in __aenter__
    self._resp = await self._coro
  File "/Users/sammuurr/PycharmProjects/GeekShop/venv/lib/python3.9/site-packages/aiohttp/client.py", line 559, in _request
    await resp.start(conn)
  File "/Users/sammuurr/PycharmProjects/GeekShop/venv/lib/python3.9/site-packages/aiohttp/client_reqrep.py", line 913, in start
    self._continue = None
  File "/Users/sammuurr/PycharmProjects/GeekShop/venv/lib/python3.9/site-packages/aiohttp/helpers.py", line 721, in __exit__
    raise asyncio.TimeoutError from None
asyncio.exceptions.TimeoutError
[2022-06-25 20:07:36,524] - [ERROR] -->  Cause exception while getting updates.
Traceback (most recent call last):
  File "/Users/sammuurr/PycharmProjects/GeekShop/venv/lib/python3.9/site-packages/aiogram/dispatcher/dispatcher.py", line 381, in start_polling
    updates = await self.bot.get_updates(
  File "/Users/sammuurr/PycharmProjects/GeekShop/venv/lib/python3.9/site-packages/aiogram/bot/bot.py", line 110, in get_updates
    result = await self.request(api.Methods.GET_UPDATES, payload)
  File "/Users/sammuurr/PycharmProjects/GeekShop/venv/lib/python3.9/site-packages/aiogram/bot/base.py", line 231, in request
    return await api.make_request(await self.get_session(), self.server, self.__token, method, data, files,
  File "/Users/sammuurr/PycharmProjects/GeekShop/venv/lib/python3.9/site-packages/aiogram/bot/api.py", line 139, in make_request
    async with session.post(url, data=req, **kwargs) as response:
  File "/Users/sammuurr/PycharmProjects/GeekShop/venv/lib/python3.9/site-packages/aiohttp/client.py", line 1138, in __aenter__
    self._resp = await self._coro
  File "/Users/sammuurr/PycharmProjects/GeekShop/venv/lib/python3.9/site-packages/aiohttp/client.py", line 559, in _request
    await resp.start(conn)
  File "/Users/sammuurr/PycharmProjects/GeekShop/venv/lib/python3.9/site-packages/aiohttp/client_reqrep.py", line 913, in start
    self._continue = None
  File "/Users/sammuurr/PycharmProjects/GeekShop/venv/lib/python3.9/site-packages/aiohttp/helpers.py", line 721, in __exit__
    raise asyncio.TimeoutError from None
asyncio.exceptions.TimeoutError
[2022-06-26 04:21:01,673] - [ERROR] -->  Cause exception while getting updates.
Traceback (most recent call last):
  File "/Users/sammuurr/PycharmProjects/GeekShop/venv/lib/python3.9/site-packages/aiogram/dispatcher/dispatcher.py", line 381, in start_polling
    updates = await self.bot.get_updates(
  File "/Users/sammuurr/PycharmProjects/GeekShop/venv/lib/python3.9/site-packages/aiogram/bot/bot.py", line 110, in get_updates
    result = await self.request(api.Methods.GET_UPDATES, payload)
  File "/Users/sammuurr/PycharmProjects/GeekShop/venv/lib/python3.9/site-packages/aiogram/bot/base.py", line 231, in request
    return await api.make_request(await self.get_session(), self.server, self.__token, method, data, files,
  File "/Users/sammuurr/PycharmProjects/GeekShop/venv/lib/python3.9/site-packages/aiogram/bot/api.py", line 139, in make_request
    async with session.post(url, data=req, **kwargs) as response:
  File "/Users/sammuurr/PycharmProjects/GeekShop/venv/lib/python3.9/site-packages/aiohttp/client.py", line 1138, in __aenter__
    self._resp = await self._coro
  File "/Users/sammuurr/PycharmProjects/GeekShop/venv/lib/python3.9/site-packages/aiohttp/client.py", line 559, in _request
    await resp.start(conn)
  File "/Users/sammuurr/PycharmProjects/GeekShop/venv/lib/python3.9/site-packages/aiohttp/client_reqrep.py", line 913, in start
    self._continue = None
  File "/Users/sammuurr/PycharmProjects/GeekShop/venv/lib/python3.9/site-packages/aiohttp/helpers.py", line 721, in __exit__
    raise asyncio.TimeoutError from None
asyncio.exceptions.TimeoutError
[2022-06-26 10:20:05,011] - [ERROR] -->  Cause exception while getting updates.
Traceback (most recent call last):
  File "/Users/sammuurr/PycharmProjects/GeekShop/venv/lib/python3.9/site-packages/aiogram/dispatcher/dispatcher.py", line 381, in start_polling
    updates = await self.bot.get_updates(
  File "/Users/sammuurr/PycharmProjects/GeekShop/venv/lib/python3.9/site-packages/aiogram/bot/bot.py", line 110, in get_updates
    result = await self.request(api.Methods.GET_UPDATES, payload)
  File "/Users/sammuurr/PycharmProjects/GeekShop/venv/lib/python3.9/site-packages/aiogram/bot/base.py", line 231, in request
    return await api.make_request(await self.get_session(), self.server, self.__token, method, data, files,
  File "/Users/sammuurr/PycharmProjects/GeekShop/venv/lib/python3.9/site-packages/aiogram/bot/api.py", line 139, in make_request
    async with session.post(url, data=req, **kwargs) as response:
  File "/Users/sammuurr/PycharmProjects/GeekShop/venv/lib/python3.9/site-packages/aiohttp/client.py", line 1138, in __aenter__
    self._resp = await self._coro
  File "/Users/sammuurr/PycharmProjects/GeekShop/venv/lib/python3.9/site-packages/aiohttp/client.py", line 559, in _request
    await resp.start(conn)
  File "/Users/sammuurr/PycharmProjects/GeekShop/venv/lib/python3.9/site-packages/aiohttp/client_reqrep.py", line 913, in start
    self._continue = None
  File "/Users/sammuurr/PycharmProjects/GeekShop/venv/lib/python3.9/site-packages/aiohttp/helpers.py", line 721, in __exit__
    raise asyncio.TimeoutError from None
asyncio.exceptions.TimeoutError
[2022-06-26 10:58:41,217] - [WARNING] -->  Goodbye!
[2022-06-26 11:01:56,639] - [WARNING] -->  Goodbye!
[2022-06-26 11:05:15,775] - [WARNING] -->  Goodbye!
[2022-06-26 11:05:29,194] - [ERROR] -->  Task exception was never retrieved
future: <Task finished name='Task-12' coro=<Dispatcher._process_polling_updates() done, defined at /Users/sammuurr/PycharmProjects/GeekShop/venv/lib/python3.9/site-packages/aiogram/dispatcher/dispatcher.py:407> exception=CantParseEntities("Can't parse entities: unexpected end of name token at byte offset 8")>
Traceback (most recent call last):
  File "/Users/sammuurr/PycharmProjects/GeekShop/handlers/inline_handlers/admin_menu/admin_menu_admins.py", line 36, in enter_add_newadmin
    await bot.send_message(
  File "/Users/sammuurr/PycharmProjects/GeekShop/venv/lib/python3.9/site-packages/aiogram/bot/bot.py", line 334, in send_message
    result = await self.request(api.Methods.SEND_MESSAGE, payload)
  File "/Users/sammuurr/PycharmProjects/GeekShop/venv/lib/python3.9/site-packages/aiogram/bot/base.py", line 231, in request
    return await api.make_request(await self.get_session(), self.server, self.__token, method, data, files,
  File "/Users/sammuurr/PycharmProjects/GeekShop/venv/lib/python3.9/site-packages/aiogram/bot/api.py", line 140, in make_request
    return check_result(method, response.content_type, response.status, await response.text())
  File "/Users/sammuurr/PycharmProjects/GeekShop/venv/lib/python3.9/site-packages/aiogram/bot/api.py", line 115, in check_result
    exceptions.BadRequest.detect(description)
  File "/Users/sammuurr/PycharmProjects/GeekShop/venv/lib/python3.9/site-packages/aiogram/utils/exceptions.py", line 140, in detect
    raise err(cls.text or description)
aiogram.utils.exceptions.ChatNotFound: Chat not found

During handling of the above exception, another exception occurred:

Traceback (most recent call last):
  File "/Users/sammuurr/PycharmProjects/GeekShop/venv/lib/python3.9/site-packages/aiogram/dispatcher/dispatcher.py", line 415, in _process_polling_updates
    for responses in itertools.chain.from_iterable(await self.process_updates(updates, fast)):
  File "/Users/sammuurr/PycharmProjects/GeekShop/venv/lib/python3.9/site-packages/aiogram/dispatcher/dispatcher.py", line 235, in process_updates
    return await asyncio.gather(*tasks)
  File "/Users/sammuurr/PycharmProjects/GeekShop/venv/lib/python3.9/site-packages/aiogram/dispatcher/handler.py", line 116, in notify
    response = await handler_obj.handler(*args, **partial_data)
  File "/Users/sammuurr/PycharmProjects/GeekShop/venv/lib/python3.9/site-packages/aiogram/dispatcher/dispatcher.py", line 256, in process_update
    return await self.message_handlers.notify(update.message)
  File "/Users/sammuurr/PycharmProjects/GeekShop/venv/lib/python3.9/site-packages/aiogram/dispatcher/handler.py", line 116, in notify
    response = await handler_obj.handler(*args, **partial_data)
  File "/Users/sammuurr/PycharmProjects/GeekShop/handlers/inline_handlers/admin_menu/admin_menu_admins.py", line 59, in enter_add_newadmin
    await bot.send_message(
  File "/Users/sammuurr/PycharmProjects/GeekShop/venv/lib/python3.9/site-packages/aiogram/bot/bot.py", line 334, in send_message
    result = await self.request(api.Methods.SEND_MESSAGE, payload)
  File "/Users/sammuurr/PycharmProjects/GeekShop/venv/lib/python3.9/site-packages/aiogram/bot/base.py", line 231, in request
    return await api.make_request(await self.get_session(), self.server, self.__token, method, data, files,
  File "/Users/sammuurr/PycharmProjects/GeekShop/venv/lib/python3.9/site-packages/aiogram/bot/api.py", line 140, in make_request
    return check_result(method, response.content_type, response.status, await response.text())
  File "/Users/sammuurr/PycharmProjects/GeekShop/venv/lib/python3.9/site-packages/aiogram/bot/api.py", line 115, in check_result
    exceptions.BadRequest.detect(description)
  File "/Users/sammuurr/PycharmProjects/GeekShop/venv/lib/python3.9/site-packages/aiogram/utils/exceptions.py", line 140, in detect
    raise err(cls.text or description)
aiogram.utils.exceptions.CantParseEntities: Can't parse entities: unexpected end of name token at byte offset 8
[2022-06-26 11:07:02,206] - [WARNING] -->  Goodbye!
[2022-06-26 11:07:14,110] - [ERROR] -->  Task exception was never retrieved
future: <Task finished name='Task-12' coro=<Dispatcher._process_polling_updates() done, defined at /Users/sammuurr/PycharmProjects/GeekShop/venv/lib/python3.9/site-packages/aiogram/dispatcher/dispatcher.py:407> exception=CantParseEntities("Can't parse entities: unexpected end of name token at byte offset 8")>
Traceback (most recent call last):
  File "/Users/sammuurr/PycharmProjects/GeekShop/handlers/inline_handlers/admin_menu/admin_menu_admins.py", line 36, in enter_add_newadmin
    await bot.send_message(
  File "/Users/sammuurr/PycharmProjects/GeekShop/venv/lib/python3.9/site-packages/aiogram/bot/bot.py", line 334, in send_message
    result = await self.request(api.Methods.SEND_MESSAGE, payload)
  File "/Users/sammuurr/PycharmProjects/GeekShop/venv/lib/python3.9/site-packages/aiogram/bot/base.py", line 231, in request
    return await api.make_request(await self.get_session(), self.server, self.__token, method, data, files,
  File "/Users/sammuurr/PycharmProjects/GeekShop/venv/lib/python3.9/site-packages/aiogram/bot/api.py", line 140, in make_request
    return check_result(method, response.content_type, response.status, await response.text())
  File "/Users/sammuurr/PycharmProjects/GeekShop/venv/lib/python3.9/site-packages/aiogram/bot/api.py", line 115, in check_result
    exceptions.BadRequest.detect(description)
  File "/Users/sammuurr/PycharmProjects/GeekShop/venv/lib/python3.9/site-packages/aiogram/utils/exceptions.py", line 140, in detect
    raise err(cls.text or description)
aiogram.utils.exceptions.ChatNotFound: Chat not found

During handling of the above exception, another exception occurred:

Traceback (most recent call last):
  File "/Users/sammuurr/PycharmProjects/GeekShop/venv/lib/python3.9/site-packages/aiogram/dispatcher/dispatcher.py", line 415, in _process_polling_updates
    for responses in itertools.chain.from_iterable(await self.process_updates(updates, fast)):
  File "/Users/sammuurr/PycharmProjects/GeekShop/venv/lib/python3.9/site-packages/aiogram/dispatcher/dispatcher.py", line 235, in process_updates
    return await asyncio.gather(*tasks)
  File "/Users/sammuurr/PycharmProjects/GeekShop/venv/lib/python3.9/site-packages/aiogram/dispatcher/handler.py", line 116, in notify
    response = await handler_obj.handler(*args, **partial_data)
  File "/Users/sammuurr/PycharmProjects/GeekShop/venv/lib/python3.9/site-packages/aiogram/dispatcher/dispatcher.py", line 256, in process_update
    return await self.message_handlers.notify(update.message)
  File "/Users/sammuurr/PycharmProjects/GeekShop/venv/lib/python3.9/site-packages/aiogram/dispatcher/handler.py", line 116, in notify
    response = await handler_obj.handler(*args, **partial_data)
  File "/Users/sammuurr/PycharmProjects/GeekShop/handlers/inline_handlers/admin_menu/admin_menu_admins.py", line 59, in enter_add_newadmin
    await bot.send_message(
  File "/Users/sammuurr/PycharmProjects/GeekShop/venv/lib/python3.9/site-packages/aiogram/bot/bot.py", line 334, in send_message
    result = await self.request(api.Methods.SEND_MESSAGE, payload)
  File "/Users/sammuurr/PycharmProjects/GeekShop/venv/lib/python3.9/site-packages/aiogram/bot/base.py", line 231, in request
    return await api.make_request(await self.get_session(), self.server, self.__token, method, data, files,
  File "/Users/sammuurr/PycharmProjects/GeekShop/venv/lib/python3.9/site-packages/aiogram/bot/api.py", line 140, in make_request
    return check_result(method, response.content_type, response.status, await response.text())
  File "/Users/sammuurr/PycharmProjects/GeekShop/venv/lib/python3.9/site-packages/aiogram/bot/api.py", line 115, in check_result
    exceptions.BadRequest.detect(description)
  File "/Users/sammuurr/PycharmProjects/GeekShop/venv/lib/python3.9/site-packages/aiogram/utils/exceptions.py", line 140, in detect
    raise err(cls.text or description)
aiogram.utils.exceptions.CantParseEntities: Can't parse entities: unexpected end of name token at byte offset 8
[2022-06-26 11:11:11,575] - [WARNING] -->  Goodbye!
[2022-06-26 11:11:20,922] - [ERROR] -->  Task exception was never retrieved
future: <Task finished name='Task-12' coro=<Dispatcher._process_polling_updates() done, defined at /Users/sammuurr/PycharmProjects/GeekShop/venv/lib/python3.9/site-packages/aiogram/dispatcher/dispatcher.py:407> exception=CantParseEntities("Can't parse entities: unexpected end of name token at byte offset 11")>
Traceback (most recent call last):
  File "/Users/sammuurr/PycharmProjects/GeekShop/handlers/inline_handlers/admin_menu/admin_menu_admins.py", line 36, in enter_add_newadmin
    await bot.send_message(
  File "/Users/sammuurr/PycharmProjects/GeekShop/venv/lib/python3.9/site-packages/aiogram/bot/bot.py", line 334, in send_message
    result = await self.request(api.Methods.SEND_MESSAGE, payload)
  File "/Users/sammuurr/PycharmProjects/GeekShop/venv/lib/python3.9/site-packages/aiogram/bot/base.py", line 231, in request
    return await api.make_request(await self.get_session(), self.server, self.__token, method, data, files,
  File "/Users/sammuurr/PycharmProjects/GeekShop/venv/lib/python3.9/site-packages/aiogram/bot/api.py", line 140, in make_request
    return check_result(method, response.content_type, response.status, await response.text())
  File "/Users/sammuurr/PycharmProjects/GeekShop/venv/lib/python3.9/site-packages/aiogram/bot/api.py", line 115, in check_result
    exceptions.BadRequest.detect(description)
  File "/Users/sammuurr/PycharmProjects/GeekShop/venv/lib/python3.9/site-packages/aiogram/utils/exceptions.py", line 140, in detect
    raise err(cls.text or description)
aiogram.utils.exceptions.ChatNotFound: Chat not found

During handling of the above exception, another exception occurred:

Traceback (most recent call last):
  File "/Users/sammuurr/PycharmProjects/GeekShop/venv/lib/python3.9/site-packages/aiogram/dispatcher/dispatcher.py", line 415, in _process_polling_updates
    for responses in itertools.chain.from_iterable(await self.process_updates(updates, fast)):
  File "/Users/sammuurr/PycharmProjects/GeekShop/venv/lib/python3.9/site-packages/aiogram/dispatcher/dispatcher.py", line 235, in process_updates
    return await asyncio.gather(*tasks)
  File "/Users/sammuurr/PycharmProjects/GeekShop/venv/lib/python3.9/site-packages/aiogram/dispatcher/handler.py", line 116, in notify
    response = await handler_obj.handler(*args, **partial_data)
  File "/Users/sammuurr/PycharmProjects/GeekShop/venv/lib/python3.9/site-packages/aiogram/dispatcher/dispatcher.py", line 256, in process_update
    return await self.message_handlers.notify(update.message)
  File "/Users/sammuurr/PycharmProjects/GeekShop/venv/lib/python3.9/site-packages/aiogram/dispatcher/handler.py", line 116, in notify
    response = await handler_obj.handler(*args, **partial_data)
  File "/Users/sammuurr/PycharmProjects/GeekShop/handlers/inline_handlers/admin_menu/admin_menu_admins.py", line 59, in enter_add_newadmin
    await bot.send_message(
  File "/Users/sammuurr/PycharmProjects/GeekShop/venv/lib/python3.9/site-packages/aiogram/bot/bot.py", line 334, in send_message
    result = await self.request(api.Methods.SEND_MESSAGE, payload)
  File "/Users/sammuurr/PycharmProjects/GeekShop/venv/lib/python3.9/site-packages/aiogram/bot/base.py", line 231, in request
    return await api.make_request(await self.get_session(), self.server, self.__token, method, data, files,
  File "/Users/sammuurr/PycharmProjects/GeekShop/venv/lib/python3.9/site-packages/aiogram/bot/api.py", line 140, in make_request
    return check_result(method, response.content_type, response.status, await response.text())
  File "/Users/sammuurr/PycharmProjects/GeekShop/venv/lib/python3.9/site-packages/aiogram/bot/api.py", line 115, in check_result
    exceptions.BadRequest.detect(description)
  File "/Users/sammuurr/PycharmProjects/GeekShop/venv/lib/python3.9/site-packages/aiogram/utils/exceptions.py", line 140, in detect
    raise err(cls.text or description)
aiogram.utils.exceptions.CantParseEntities: Can't parse entities: unexpected end of name token at byte offset 11
[2022-06-26 11:11:31,816] - [WARNING] -->  Goodbye!
[2022-06-26 11:11:39,664] - [ERROR] -->  Task exception was never retrieved
future: <Task finished name='Task-12' coro=<Dispatcher._process_polling_updates() done, defined at /Users/sammuurr/PycharmProjects/GeekShop/venv/lib/python3.9/site-packages/aiogram/dispatcher/dispatcher.py:407> exception=CantParseEntities("Can't parse entities: unexpected end of name token at byte offset 8")>
Traceback (most recent call last):
  File "/Users/sammuurr/PycharmProjects/GeekShop/handlers/inline_handlers/admin_menu/admin_menu_admins.py", line 36, in enter_add_newadmin
    await bot.send_message(
  File "/Users/sammuurr/PycharmProjects/GeekShop/venv/lib/python3.9/site-packages/aiogram/bot/bot.py", line 334, in send_message
    result = await self.request(api.Methods.SEND_MESSAGE, payload)
  File "/Users/sammuurr/PycharmProjects/GeekShop/venv/lib/python3.9/site-packages/aiogram/bot/base.py", line 231, in request
    return await api.make_request(await self.get_session(), self.server, self.__token, method, data, files,
  File "/Users/sammuurr/PycharmProjects/GeekShop/venv/lib/python3.9/site-packages/aiogram/bot/api.py", line 140, in make_request
    return check_result(method, response.content_type, response.status, await response.text())
  File "/Users/sammuurr/PycharmProjects/GeekShop/venv/lib/python3.9/site-packages/aiogram/bot/api.py", line 115, in check_result
    exceptions.BadRequest.detect(description)
  File "/Users/sammuurr/PycharmProjects/GeekShop/venv/lib/python3.9/site-packages/aiogram/utils/exceptions.py", line 140, in detect
    raise err(cls.text or description)
aiogram.utils.exceptions.ChatNotFound: Chat not found

During handling of the above exception, another exception occurred:

Traceback (most recent call last):
  File "/Users/sammuurr/PycharmProjects/GeekShop/venv/lib/python3.9/site-packages/aiogram/dispatcher/dispatcher.py", line 415, in _process_polling_updates
    for responses in itertools.chain.from_iterable(await self.process_updates(updates, fast)):
  File "/Users/sammuurr/PycharmProjects/GeekShop/venv/lib/python3.9/site-packages/aiogram/dispatcher/dispatcher.py", line 235, in process_updates
    return await asyncio.gather(*tasks)
  File "/Users/sammuurr/PycharmProjects/GeekShop/venv/lib/python3.9/site-packages/aiogram/dispatcher/handler.py", line 116, in notify
    response = await handler_obj.handler(*args, **partial_data)
  File "/Users/sammuurr/PycharmProjects/GeekShop/venv/lib/python3.9/site-packages/aiogram/dispatcher/dispatcher.py", line 256, in process_update
    return await self.message_handlers.notify(update.message)
  File "/Users/sammuurr/PycharmProjects/GeekShop/venv/lib/python3.9/site-packages/aiogram/dispatcher/handler.py", line 116, in notify
    response = await handler_obj.handler(*args, **partial_data)
  File "/Users/sammuurr/PycharmProjects/GeekShop/handlers/inline_handlers/admin_menu/admin_menu_admins.py", line 59, in enter_add_newadmin
    await bot.send_message(
  File "/Users/sammuurr/PycharmProjects/GeekShop/venv/lib/python3.9/site-packages/aiogram/bot/bot.py", line 334, in send_message
    result = await self.request(api.Methods.SEND_MESSAGE, payload)
  File "/Users/sammuurr/PycharmProjects/GeekShop/venv/lib/python3.9/site-packages/aiogram/bot/base.py", line 231, in request
    return await api.make_request(await self.get_session(), self.server, self.__token, method, data, files,
  File "/Users/sammuurr/PycharmProjects/GeekShop/venv/lib/python3.9/site-packages/aiogram/bot/api.py", line 140, in make_request
    return check_result(method, response.content_type, response.status, await response.text())
  File "/Users/sammuurr/PycharmProjects/GeekShop/venv/lib/python3.9/site-packages/aiogram/bot/api.py", line 115, in check_result
    exceptions.BadRequest.detect(description)
  File "/Users/sammuurr/PycharmProjects/GeekShop/venv/lib/python3.9/site-packages/aiogram/utils/exceptions.py", line 140, in detect
    raise err(cls.text or description)
aiogram.utils.exceptions.CantParseEntities: Can't parse entities: unexpected end of name token at byte offset 8
[2022-06-26 11:13:10,185] - [WARNING] -->  Goodbye!
[2022-06-26 11:19:12,472] - [WARNING] -->  Goodbye!
[2022-06-26 11:25:01,920] - [WARNING] -->  Goodbye!
[2022-06-26 11:28:20,489] - [WARNING] -->  Goodbye!
[2022-06-26 11:29:33,102] - [WARNING] -->  Goodbye!
[2022-06-26 11:31:18,766] - [WARNING] -->  Goodbye!
[2022-06-26 12:17:47,881] - [ERROR] -->  Cause exception while getting updates.
Traceback (most recent call last):
  File "/Users/sammuurr/PycharmProjects/GeekShop/venv/lib/python3.9/site-packages/aiogram/dispatcher/dispatcher.py", line 381, in start_polling
    updates = await self.bot.get_updates(
  File "/Users/sammuurr/PycharmProjects/GeekShop/venv/lib/python3.9/site-packages/aiogram/bot/bot.py", line 110, in get_updates
    result = await self.request(api.Methods.GET_UPDATES, payload)
  File "/Users/sammuurr/PycharmProjects/GeekShop/venv/lib/python3.9/site-packages/aiogram/bot/base.py", line 231, in request
    return await api.make_request(await self.get_session(), self.server, self.__token, method, data, files,
  File "/Users/sammuurr/PycharmProjects/GeekShop/venv/lib/python3.9/site-packages/aiogram/bot/api.py", line 139, in make_request
    async with session.post(url, data=req, **kwargs) as response:
  File "/Users/sammuurr/PycharmProjects/GeekShop/venv/lib/python3.9/site-packages/aiohttp/client.py", line 1138, in __aenter__
    self._resp = await self._coro
  File "/Users/sammuurr/PycharmProjects/GeekShop/venv/lib/python3.9/site-packages/aiohttp/client.py", line 559, in _request
    await resp.start(conn)
  File "/Users/sammuurr/PycharmProjects/GeekShop/venv/lib/python3.9/site-packages/aiohttp/client_reqrep.py", line 913, in start
    self._continue = None
  File "/Users/sammuurr/PycharmProjects/GeekShop/venv/lib/python3.9/site-packages/aiohttp/helpers.py", line 721, in __exit__
    raise asyncio.TimeoutError from None
asyncio.exceptions.TimeoutError
[2022-06-26 19:25:13,203] - [ERROR] -->  Cause exception while getting updates.
Traceback (most recent call last):
  File "/Users/sammuurr/PycharmProjects/GeekShop/venv/lib/python3.9/site-packages/aiogram/dispatcher/dispatcher.py", line 381, in start_polling
    updates = await self.bot.get_updates(
  File "/Users/sammuurr/PycharmProjects/GeekShop/venv/lib/python3.9/site-packages/aiogram/bot/bot.py", line 110, in get_updates
    result = await self.request(api.Methods.GET_UPDATES, payload)
  File "/Users/sammuurr/PycharmProjects/GeekShop/venv/lib/python3.9/site-packages/aiogram/bot/base.py", line 231, in request
    return await api.make_request(await self.get_session(), self.server, self.__token, method, data, files,
  File "/Users/sammuurr/PycharmProjects/GeekShop/venv/lib/python3.9/site-packages/aiogram/bot/api.py", line 139, in make_request
    async with session.post(url, data=req, **kwargs) as response:
  File "/Users/sammuurr/PycharmProjects/GeekShop/venv/lib/python3.9/site-packages/aiohttp/client.py", line 1138, in __aenter__
    self._resp = await self._coro
  File "/Users/sammuurr/PycharmProjects/GeekShop/venv/lib/python3.9/site-packages/aiohttp/client.py", line 559, in _request
    await resp.start(conn)
  File "/Users/sammuurr/PycharmProjects/GeekShop/venv/lib/python3.9/site-packages/aiohttp/client_reqrep.py", line 913, in start
    self._continue = None
  File "/Users/sammuurr/PycharmProjects/GeekShop/venv/lib/python3.9/site-packages/aiohttp/helpers.py", line 721, in __exit__
    raise asyncio.TimeoutError from None
asyncio.exceptions.TimeoutError
[2022-06-26 22:18:50,881] - [ERROR] -->  Cause exception while getting updates.
Traceback (most recent call last):
  File "/Users/sammuurr/PycharmProjects/GeekShop/venv/lib/python3.9/site-packages/aiogram/dispatcher/dispatcher.py", line 381, in start_polling
    updates = await self.bot.get_updates(
  File "/Users/sammuurr/PycharmProjects/GeekShop/venv/lib/python3.9/site-packages/aiogram/bot/bot.py", line 110, in get_updates
    result = await self.request(api.Methods.GET_UPDATES, payload)
  File "/Users/sammuurr/PycharmProjects/GeekShop/venv/lib/python3.9/site-packages/aiogram/bot/base.py", line 231, in request
    return await api.make_request(await self.get_session(), self.server, self.__token, method, data, files,
  File "/Users/sammuurr/PycharmProjects/GeekShop/venv/lib/python3.9/site-packages/aiogram/bot/api.py", line 139, in make_request
    async with session.post(url, data=req, **kwargs) as response:
  File "/Users/sammuurr/PycharmProjects/GeekShop/venv/lib/python3.9/site-packages/aiohttp/client.py", line 1138, in __aenter__
    self._resp = await self._coro
  File "/Users/sammuurr/PycharmProjects/GeekShop/venv/lib/python3.9/site-packages/aiohttp/client.py", line 559, in _request
    await resp.start(conn)
  File "/Users/sammuurr/PycharmProjects/GeekShop/venv/lib/python3.9/site-packages/aiohttp/client_reqrep.py", line 913, in start
    self._continue = None
  File "/Users/sammuurr/PycharmProjects/GeekShop/venv/lib/python3.9/site-packages/aiohttp/helpers.py", line 721, in __exit__
    raise asyncio.TimeoutError from None
asyncio.exceptions.TimeoutError
[2022-06-27 05:26:10,525] - [ERROR] -->  Cause exception while getting updates.
Traceback (most recent call last):
  File "/Users/sammuurr/PycharmProjects/GeekShop/venv/lib/python3.9/site-packages/aiogram/dispatcher/dispatcher.py", line 381, in start_polling
    updates = await self.bot.get_updates(
  File "/Users/sammuurr/PycharmProjects/GeekShop/venv/lib/python3.9/site-packages/aiogram/bot/bot.py", line 110, in get_updates
    result = await self.request(api.Methods.GET_UPDATES, payload)
  File "/Users/sammuurr/PycharmProjects/GeekShop/venv/lib/python3.9/site-packages/aiogram/bot/base.py", line 231, in request
    return await api.make_request(await self.get_session(), self.server, self.__token, method, data, files,
  File "/Users/sammuurr/PycharmProjects/GeekShop/venv/lib/python3.9/site-packages/aiogram/bot/api.py", line 139, in make_request
    async with session.post(url, data=req, **kwargs) as response:
  File "/Users/sammuurr/PycharmProjects/GeekShop/venv/lib/python3.9/site-packages/aiohttp/client.py", line 1138, in __aenter__
    self._resp = await self._coro
  File "/Users/sammuurr/PycharmProjects/GeekShop/venv/lib/python3.9/site-packages/aiohttp/client.py", line 559, in _request
    await resp.start(conn)
  File "/Users/sammuurr/PycharmProjects/GeekShop/venv/lib/python3.9/site-packages/aiohttp/client_reqrep.py", line 913, in start
    self._continue = None
  File "/Users/sammuurr/PycharmProjects/GeekShop/venv/lib/python3.9/site-packages/aiohttp/helpers.py", line 721, in __exit__
    raise asyncio.TimeoutError from None
asyncio.exceptions.TimeoutError
[2022-06-27 12:54:39,663] - [ERROR] -->  Cause exception while getting updates.
Traceback (most recent call last):
  File "/Users/sammuurr/PycharmProjects/GeekShop/venv/lib/python3.9/site-packages/aiogram/dispatcher/dispatcher.py", line 381, in start_polling
    updates = await self.bot.get_updates(
  File "/Users/sammuurr/PycharmProjects/GeekShop/venv/lib/python3.9/site-packages/aiogram/bot/bot.py", line 110, in get_updates
    result = await self.request(api.Methods.GET_UPDATES, payload)
  File "/Users/sammuurr/PycharmProjects/GeekShop/venv/lib/python3.9/site-packages/aiogram/bot/base.py", line 231, in request
    return await api.make_request(await self.get_session(), self.server, self.__token, method, data, files,
  File "/Users/sammuurr/PycharmProjects/GeekShop/venv/lib/python3.9/site-packages/aiogram/bot/api.py", line 139, in make_request
    async with session.post(url, data=req, **kwargs) as response:
  File "/Users/sammuurr/PycharmProjects/GeekShop/venv/lib/python3.9/site-packages/aiohttp/client.py", line 1138, in __aenter__
    self._resp = await self._coro
  File "/Users/sammuurr/PycharmProjects/GeekShop/venv/lib/python3.9/site-packages/aiohttp/client.py", line 559, in _request
    await resp.start(conn)
  File "/Users/sammuurr/PycharmProjects/GeekShop/venv/lib/python3.9/site-packages/aiohttp/client_reqrep.py", line 913, in start
    self._continue = None
  File "/Users/sammuurr/PycharmProjects/GeekShop/venv/lib/python3.9/site-packages/aiohttp/helpers.py", line 721, in __exit__
    raise asyncio.TimeoutError from None
asyncio.exceptions.TimeoutError
[2022-06-27 12:54:44,706] - [ERROR] -->  Cause exception while getting updates.
Traceback (most recent call last):
  File "/Users/sammuurr/PycharmProjects/GeekShop/venv/lib/python3.9/site-packages/aiohttp/connector.py", line 1154, in _create_direct_connection
    hosts = await asyncio.shield(host_resolved)
  File "/Users/sammuurr/PycharmProjects/GeekShop/venv/lib/python3.9/site-packages/aiohttp/connector.py", line 880, in _resolve_host
    addrs = await self._resolver.resolve(host, port, family=self._family)
  File "/Users/sammuurr/PycharmProjects/GeekShop/venv/lib/python3.9/site-packages/aiohttp/resolver.py", line 33, in resolve
    infos = await self._loop.getaddrinfo(
  File "/Library/Frameworks/Python.framework/Versions/3.9/lib/python3.9/asyncio/base_events.py", line 856, in getaddrinfo
    return await self.run_in_executor(
  File "/Library/Frameworks/Python.framework/Versions/3.9/lib/python3.9/concurrent/futures/thread.py", line 52, in run
    result = self.fn(*self.args, **self.kwargs)
  File "/Library/Frameworks/Python.framework/Versions/3.9/lib/python3.9/socket.py", line 953, in getaddrinfo
    for res in _socket.getaddrinfo(host, port, family, type, proto, flags):
socket.gaierror: [Errno 8] nodename nor servname provided, or not known

The above exception was the direct cause of the following exception:

Traceback (most recent call last):
  File "/Users/sammuurr/PycharmProjects/GeekShop/venv/lib/python3.9/site-packages/aiogram/bot/api.py", line 139, in make_request
    async with session.post(url, data=req, **kwargs) as response:
  File "/Users/sammuurr/PycharmProjects/GeekShop/venv/lib/python3.9/site-packages/aiohttp/client.py", line 1138, in __aenter__
    self._resp = await self._coro
  File "/Users/sammuurr/PycharmProjects/GeekShop/venv/lib/python3.9/site-packages/aiohttp/client.py", line 535, in _request
    conn = await self._connector.connect(
  File "/Users/sammuurr/PycharmProjects/GeekShop/venv/lib/python3.9/site-packages/aiohttp/connector.py", line 542, in connect
    proto = await self._create_connection(req, traces, timeout)
  File "/Users/sammuurr/PycharmProjects/GeekShop/venv/lib/python3.9/site-packages/aiohttp/connector.py", line 907, in _create_connection
    _, proto = await self._create_direct_connection(req, traces, timeout)
  File "/Users/sammuurr/PycharmProjects/GeekShop/venv/lib/python3.9/site-packages/aiohttp/connector.py", line 1166, in _create_direct_connection
    raise ClientConnectorError(req.connection_key, exc) from exc
aiohttp.client_exceptions.ClientConnectorError: Cannot connect to host api.telegram.org:443 ssl:default [nodename nor servname provided, or not known]

During handling of the above exception, another exception occurred:

Traceback (most recent call last):
  File "/Users/sammuurr/PycharmProjects/GeekShop/venv/lib/python3.9/site-packages/aiogram/dispatcher/dispatcher.py", line 381, in start_polling
    updates = await self.bot.get_updates(
  File "/Users/sammuurr/PycharmProjects/GeekShop/venv/lib/python3.9/site-packages/aiogram/bot/bot.py", line 110, in get_updates
    result = await self.request(api.Methods.GET_UPDATES, payload)
  File "/Users/sammuurr/PycharmProjects/GeekShop/venv/lib/python3.9/site-packages/aiogram/bot/base.py", line 231, in request
    return await api.make_request(await self.get_session(), self.server, self.__token, method, data, files,
  File "/Users/sammuurr/PycharmProjects/GeekShop/venv/lib/python3.9/site-packages/aiogram/bot/api.py", line 142, in make_request
    raise exceptions.NetworkError(f"aiohttp client throws an error: {e.__class__.__name__}: {e}")
aiogram.utils.exceptions.NetworkError: Aiohttp client throws an error: ClientConnectorError: Cannot connect to host api.telegram.org:443 ssl:default [nodename nor servname provided, or not known]
[2022-06-27 12:54:49,737] - [ERROR] -->  Cause exception while getting updates.
Traceback (most recent call last):
  File "/Users/sammuurr/PycharmProjects/GeekShop/venv/lib/python3.9/site-packages/aiohttp/connector.py", line 1154, in _create_direct_connection
    hosts = await asyncio.shield(host_resolved)
  File "/Users/sammuurr/PycharmProjects/GeekShop/venv/lib/python3.9/site-packages/aiohttp/connector.py", line 880, in _resolve_host
    addrs = await self._resolver.resolve(host, port, family=self._family)
  File "/Users/sammuurr/PycharmProjects/GeekShop/venv/lib/python3.9/site-packages/aiohttp/resolver.py", line 33, in resolve
    infos = await self._loop.getaddrinfo(
  File "/Library/Frameworks/Python.framework/Versions/3.9/lib/python3.9/asyncio/base_events.py", line 856, in getaddrinfo
    return await self.run_in_executor(
  File "/Library/Frameworks/Python.framework/Versions/3.9/lib/python3.9/concurrent/futures/thread.py", line 52, in run
    result = self.fn(*self.args, **self.kwargs)
  File "/Library/Frameworks/Python.framework/Versions/3.9/lib/python3.9/socket.py", line 953, in getaddrinfo
    for res in _socket.getaddrinfo(host, port, family, type, proto, flags):
socket.gaierror: [Errno 8] nodename nor servname provided, or not known

The above exception was the direct cause of the following exception:

Traceback (most recent call last):
  File "/Users/sammuurr/PycharmProjects/GeekShop/venv/lib/python3.9/site-packages/aiogram/bot/api.py", line 139, in make_request
    async with session.post(url, data=req, **kwargs) as response:
  File "/Users/sammuurr/PycharmProjects/GeekShop/venv/lib/python3.9/site-packages/aiohttp/client.py", line 1138, in __aenter__
    self._resp = await self._coro
  File "/Users/sammuurr/PycharmProjects/GeekShop/venv/lib/python3.9/site-packages/aiohttp/client.py", line 535, in _request
    conn = await self._connector.connect(
  File "/Users/sammuurr/PycharmProjects/GeekShop/venv/lib/python3.9/site-packages/aiohttp/connector.py", line 542, in connect
    proto = await self._create_connection(req, traces, timeout)
  File "/Users/sammuurr/PycharmProjects/GeekShop/venv/lib/python3.9/site-packages/aiohttp/connector.py", line 907, in _create_connection
    _, proto = await self._create_direct_connection(req, traces, timeout)
  File "/Users/sammuurr/PycharmProjects/GeekShop/venv/lib/python3.9/site-packages/aiohttp/connector.py", line 1166, in _create_direct_connection
    raise ClientConnectorError(req.connection_key, exc) from exc
aiohttp.client_exceptions.ClientConnectorError: Cannot connect to host api.telegram.org:443 ssl:default [nodename nor servname provided, or not known]

During handling of the above exception, another exception occurred:

Traceback (most recent call last):
  File "/Users/sammuurr/PycharmProjects/GeekShop/venv/lib/python3.9/site-packages/aiogram/dispatcher/dispatcher.py", line 381, in start_polling
    updates = await self.bot.get_updates(
  File "/Users/sammuurr/PycharmProjects/GeekShop/venv/lib/python3.9/site-packages/aiogram/bot/bot.py", line 110, in get_updates
    result = await self.request(api.Methods.GET_UPDATES, payload)
  File "/Users/sammuurr/PycharmProjects/GeekShop/venv/lib/python3.9/site-packages/aiogram/bot/base.py", line 231, in request
    return await api.make_request(await self.get_session(), self.server, self.__token, method, data, files,
  File "/Users/sammuurr/PycharmProjects/GeekShop/venv/lib/python3.9/site-packages/aiogram/bot/api.py", line 142, in make_request
    raise exceptions.NetworkError(f"aiohttp client throws an error: {e.__class__.__name__}: {e}")
aiogram.utils.exceptions.NetworkError: Aiohttp client throws an error: ClientConnectorError: Cannot connect to host api.telegram.org:443 ssl:default [nodename nor servname provided, or not known]
[2022-06-27 12:54:54,751] - [ERROR] -->  Cause exception while getting updates.
Traceback (most recent call last):
  File "/Users/sammuurr/PycharmProjects/GeekShop/venv/lib/python3.9/site-packages/aiohttp/connector.py", line 1154, in _create_direct_connection
    hosts = await asyncio.shield(host_resolved)
  File "/Users/sammuurr/PycharmProjects/GeekShop/venv/lib/python3.9/site-packages/aiohttp/connector.py", line 880, in _resolve_host
    addrs = await self._resolver.resolve(host, port, family=self._family)
  File "/Users/sammuurr/PycharmProjects/GeekShop/venv/lib/python3.9/site-packages/aiohttp/resolver.py", line 33, in resolve
    infos = await self._loop.getaddrinfo(
  File "/Library/Frameworks/Python.framework/Versions/3.9/lib/python3.9/asyncio/base_events.py", line 856, in getaddrinfo
    return await self.run_in_executor(
  File "/Library/Frameworks/Python.framework/Versions/3.9/lib/python3.9/concurrent/futures/thread.py", line 52, in run
    result = self.fn(*self.args, **self.kwargs)
  File "/Library/Frameworks/Python.framework/Versions/3.9/lib/python3.9/socket.py", line 953, in getaddrinfo
    for res in _socket.getaddrinfo(host, port, family, type, proto, flags):
socket.gaierror: [Errno 8] nodename nor servname provided, or not known

The above exception was the direct cause of the following exception:

Traceback (most recent call last):
  File "/Users/sammuurr/PycharmProjects/GeekShop/venv/lib/python3.9/site-packages/aiogram/bot/api.py", line 139, in make_request
    async with session.post(url, data=req, **kwargs) as response:
  File "/Users/sammuurr/PycharmProjects/GeekShop/venv/lib/python3.9/site-packages/aiohttp/client.py", line 1138, in __aenter__
    self._resp = await self._coro
  File "/Users/sammuurr/PycharmProjects/GeekShop/venv/lib/python3.9/site-packages/aiohttp/client.py", line 535, in _request
    conn = await self._connector.connect(
  File "/Users/sammuurr/PycharmProjects/GeekShop/venv/lib/python3.9/site-packages/aiohttp/connector.py", line 542, in connect
    proto = await self._create_connection(req, traces, timeout)
  File "/Users/sammuurr/PycharmProjects/GeekShop/venv/lib/python3.9/site-packages/aiohttp/connector.py", line 907, in _create_connection
    _, proto = await self._create_direct_connection(req, traces, timeout)
  File "/Users/sammuurr/PycharmProjects/GeekShop/venv/lib/python3.9/site-packages/aiohttp/connector.py", line 1166, in _create_direct_connection
    raise ClientConnectorError(req.connection_key, exc) from exc
aiohttp.client_exceptions.ClientConnectorError: Cannot connect to host api.telegram.org:443 ssl:default [nodename nor servname provided, or not known]

During handling of the above exception, another exception occurred:

Traceback (most recent call last):
  File "/Users/sammuurr/PycharmProjects/GeekShop/venv/lib/python3.9/site-packages/aiogram/dispatcher/dispatcher.py", line 381, in start_polling
    updates = await self.bot.get_updates(
  File "/Users/sammuurr/PycharmProjects/GeekShop/venv/lib/python3.9/site-packages/aiogram/bot/bot.py", line 110, in get_updates
    result = await self.request(api.Methods.GET_UPDATES, payload)
  File "/Users/sammuurr/PycharmProjects/GeekShop/venv/lib/python3.9/site-packages/aiogram/bot/base.py", line 231, in request
    return await api.make_request(await self.get_session(), self.server, self.__token, method, data, files,
  File "/Users/sammuurr/PycharmProjects/GeekShop/venv/lib/python3.9/site-packages/aiogram/bot/api.py", line 142, in make_request
    raise exceptions.NetworkError(f"aiohttp client throws an error: {e.__class__.__name__}: {e}")
aiogram.utils.exceptions.NetworkError: Aiohttp client throws an error: ClientConnectorError: Cannot connect to host api.telegram.org:443 ssl:default [nodename nor servname provided, or not known]
[2022-06-27 12:54:59,764] - [ERROR] -->  Cause exception while getting updates.
Traceback (most recent call last):
  File "/Users/sammuurr/PycharmProjects/GeekShop/venv/lib/python3.9/site-packages/aiohttp/connector.py", line 1154, in _create_direct_connection
    hosts = await asyncio.shield(host_resolved)
  File "/Users/sammuurr/PycharmProjects/GeekShop/venv/lib/python3.9/site-packages/aiohttp/connector.py", line 880, in _resolve_host
    addrs = await self._resolver.resolve(host, port, family=self._family)
  File "/Users/sammuurr/PycharmProjects/GeekShop/venv/lib/python3.9/site-packages/aiohttp/resolver.py", line 33, in resolve
    infos = await self._loop.getaddrinfo(
  File "/Library/Frameworks/Python.framework/Versions/3.9/lib/python3.9/asyncio/base_events.py", line 856, in getaddrinfo
    return await self.run_in_executor(
  File "/Library/Frameworks/Python.framework/Versions/3.9/lib/python3.9/concurrent/futures/thread.py", line 52, in run
    result = self.fn(*self.args, **self.kwargs)
  File "/Library/Frameworks/Python.framework/Versions/3.9/lib/python3.9/socket.py", line 953, in getaddrinfo
    for res in _socket.getaddrinfo(host, port, family, type, proto, flags):
socket.gaierror: [Errno 8] nodename nor servname provided, or not known

The above exception was the direct cause of the following exception:

Traceback (most recent call last):
  File "/Users/sammuurr/PycharmProjects/GeekShop/venv/lib/python3.9/site-packages/aiogram/bot/api.py", line 139, in make_request
    async with session.post(url, data=req, **kwargs) as response:
  File "/Users/sammuurr/PycharmProjects/GeekShop/venv/lib/python3.9/site-packages/aiohttp/client.py", line 1138, in __aenter__
    self._resp = await self._coro
  File "/Users/sammuurr/PycharmProjects/GeekShop/venv/lib/python3.9/site-packages/aiohttp/client.py", line 535, in _request
    conn = await self._connector.connect(
  File "/Users/sammuurr/PycharmProjects/GeekShop/venv/lib/python3.9/site-packages/aiohttp/connector.py", line 542, in connect
    proto = await self._create_connection(req, traces, timeout)
  File "/Users/sammuurr/PycharmProjects/GeekShop/venv/lib/python3.9/site-packages/aiohttp/connector.py", line 907, in _create_connection
    _, proto = await self._create_direct_connection(req, traces, timeout)
  File "/Users/sammuurr/PycharmProjects/GeekShop/venv/lib/python3.9/site-packages/aiohttp/connector.py", line 1166, in _create_direct_connection
    raise ClientConnectorError(req.connection_key, exc) from exc
aiohttp.client_exceptions.ClientConnectorError: Cannot connect to host api.telegram.org:443 ssl:default [nodename nor servname provided, or not known]

During handling of the above exception, another exception occurred:

Traceback (most recent call last):
  File "/Users/sammuurr/PycharmProjects/GeekShop/venv/lib/python3.9/site-packages/aiogram/dispatcher/dispatcher.py", line 381, in start_polling
    updates = await self.bot.get_updates(
  File "/Users/sammuurr/PycharmProjects/GeekShop/venv/lib/python3.9/site-packages/aiogram/bot/bot.py", line 110, in get_updates
    result = await self.request(api.Methods.GET_UPDATES, payload)
  File "/Users/sammuurr/PycharmProjects/GeekShop/venv/lib/python3.9/site-packages/aiogram/bot/base.py", line 231, in request
    return await api.make_request(await self.get_session(), self.server, self.__token, method, data, files,
  File "/Users/sammuurr/PycharmProjects/GeekShop/venv/lib/python3.9/site-packages/aiogram/bot/api.py", line 142, in make_request
    raise exceptions.NetworkError(f"aiohttp client throws an error: {e.__class__.__name__}: {e}")
aiogram.utils.exceptions.NetworkError: Aiohttp client throws an error: ClientConnectorError: Cannot connect to host api.telegram.org:443 ssl:default [nodename nor servname provided, or not known]
[2022-06-27 12:55:04,779] - [ERROR] -->  Cause exception while getting updates.
Traceback (most recent call last):
  File "/Users/sammuurr/PycharmProjects/GeekShop/venv/lib/python3.9/site-packages/aiohttp/connector.py", line 1154, in _create_direct_connection
    hosts = await asyncio.shield(host_resolved)
  File "/Users/sammuurr/PycharmProjects/GeekShop/venv/lib/python3.9/site-packages/aiohttp/connector.py", line 880, in _resolve_host
    addrs = await self._resolver.resolve(host, port, family=self._family)
  File "/Users/sammuurr/PycharmProjects/GeekShop/venv/lib/python3.9/site-packages/aiohttp/resolver.py", line 33, in resolve
    infos = await self._loop.getaddrinfo(
  File "/Library/Frameworks/Python.framework/Versions/3.9/lib/python3.9/asyncio/base_events.py", line 856, in getaddrinfo
    return await self.run_in_executor(
  File "/Library/Frameworks/Python.framework/Versions/3.9/lib/python3.9/concurrent/futures/thread.py", line 52, in run
    result = self.fn(*self.args, **self.kwargs)
  File "/Library/Frameworks/Python.framework/Versions/3.9/lib/python3.9/socket.py", line 953, in getaddrinfo
    for res in _socket.getaddrinfo(host, port, family, type, proto, flags):
socket.gaierror: [Errno 8] nodename nor servname provided, or not known

The above exception was the direct cause of the following exception:

Traceback (most recent call last):
  File "/Users/sammuurr/PycharmProjects/GeekShop/venv/lib/python3.9/site-packages/aiogram/bot/api.py", line 139, in make_request
    async with session.post(url, data=req, **kwargs) as response:
  File "/Users/sammuurr/PycharmProjects/GeekShop/venv/lib/python3.9/site-packages/aiohttp/client.py", line 1138, in __aenter__
    self._resp = await self._coro
  File "/Users/sammuurr/PycharmProjects/GeekShop/venv/lib/python3.9/site-packages/aiohttp/client.py", line 535, in _request
    conn = await self._connector.connect(
  File "/Users/sammuurr/PycharmProjects/GeekShop/venv/lib/python3.9/site-packages/aiohttp/connector.py", line 542, in connect
    proto = await self._create_connection(req, traces, timeout)
  File "/Users/sammuurr/PycharmProjects/GeekShop/venv/lib/python3.9/site-packages/aiohttp/connector.py", line 907, in _create_connection
    _, proto = await self._create_direct_connection(req, traces, timeout)
  File "/Users/sammuurr/PycharmProjects/GeekShop/venv/lib/python3.9/site-packages/aiohttp/connector.py", line 1166, in _create_direct_connection
    raise ClientConnectorError(req.connection_key, exc) from exc
aiohttp.client_exceptions.ClientConnectorError: Cannot connect to host api.telegram.org:443 ssl:default [nodename nor servname provided, or not known]

During handling of the above exception, another exception occurred:

Traceback (most recent call last):
  File "/Users/sammuurr/PycharmProjects/GeekShop/venv/lib/python3.9/site-packages/aiogram/dispatcher/dispatcher.py", line 381, in start_polling
    updates = await self.bot.get_updates(
  File "/Users/sammuurr/PycharmProjects/GeekShop/venv/lib/python3.9/site-packages/aiogram/bot/bot.py", line 110, in get_updates
    result = await self.request(api.Methods.GET_UPDATES, payload)
  File "/Users/sammuurr/PycharmProjects/GeekShop/venv/lib/python3.9/site-packages/aiogram/bot/base.py", line 231, in request
    return await api.make_request(await self.get_session(), self.server, self.__token, method, data, files,
  File "/Users/sammuurr/PycharmProjects/GeekShop/venv/lib/python3.9/site-packages/aiogram/bot/api.py", line 142, in make_request
    raise exceptions.NetworkError(f"aiohttp client throws an error: {e.__class__.__name__}: {e}")
aiogram.utils.exceptions.NetworkError: Aiohttp client throws an error: ClientConnectorError: Cannot connect to host api.telegram.org:443 ssl:default [nodename nor servname provided, or not known]
[2022-06-27 12:55:09,791] - [ERROR] -->  Cause exception while getting updates.
Traceback (most recent call last):
  File "/Users/sammuurr/PycharmProjects/GeekShop/venv/lib/python3.9/site-packages/aiohttp/connector.py", line 1154, in _create_direct_connection
    hosts = await asyncio.shield(host_resolved)
  File "/Users/sammuurr/PycharmProjects/GeekShop/venv/lib/python3.9/site-packages/aiohttp/connector.py", line 880, in _resolve_host
    addrs = await self._resolver.resolve(host, port, family=self._family)
  File "/Users/sammuurr/PycharmProjects/GeekShop/venv/lib/python3.9/site-packages/aiohttp/resolver.py", line 33, in resolve
    infos = await self._loop.getaddrinfo(
  File "/Library/Frameworks/Python.framework/Versions/3.9/lib/python3.9/asyncio/base_events.py", line 856, in getaddrinfo
    return await self.run_in_executor(
  File "/Library/Frameworks/Python.framework/Versions/3.9/lib/python3.9/concurrent/futures/thread.py", line 52, in run
    result = self.fn(*self.args, **self.kwargs)
  File "/Library/Frameworks/Python.framework/Versions/3.9/lib/python3.9/socket.py", line 953, in getaddrinfo
    for res in _socket.getaddrinfo(host, port, family, type, proto, flags):
socket.gaierror: [Errno 8] nodename nor servname provided, or not known

The above exception was the direct cause of the following exception:

Traceback (most recent call last):
  File "/Users/sammuurr/PycharmProjects/GeekShop/venv/lib/python3.9/site-packages/aiogram/bot/api.py", line 139, in make_request
    async with session.post(url, data=req, **kwargs) as response:
  File "/Users/sammuurr/PycharmProjects/GeekShop/venv/lib/python3.9/site-packages/aiohttp/client.py", line 1138, in __aenter__
    self._resp = await self._coro
  File "/Users/sammuurr/PycharmProjects/GeekShop/venv/lib/python3.9/site-packages/aiohttp/client.py", line 535, in _request
    conn = await self._connector.connect(
  File "/Users/sammuurr/PycharmProjects/GeekShop/venv/lib/python3.9/site-packages/aiohttp/connector.py", line 542, in connect
    proto = await self._create_connection(req, traces, timeout)
  File "/Users/sammuurr/PycharmProjects/GeekShop/venv/lib/python3.9/site-packages/aiohttp/connector.py", line 907, in _create_connection
    _, proto = await self._create_direct_connection(req, traces, timeout)
  File "/Users/sammuurr/PycharmProjects/GeekShop/venv/lib/python3.9/site-packages/aiohttp/connector.py", line 1166, in _create_direct_connection
    raise ClientConnectorError(req.connection_key, exc) from exc
aiohttp.client_exceptions.ClientConnectorError: Cannot connect to host api.telegram.org:443 ssl:default [nodename nor servname provided, or not known]

During handling of the above exception, another exception occurred:

Traceback (most recent call last):
  File "/Users/sammuurr/PycharmProjects/GeekShop/venv/lib/python3.9/site-packages/aiogram/dispatcher/dispatcher.py", line 381, in start_polling
    updates = await self.bot.get_updates(
  File "/Users/sammuurr/PycharmProjects/GeekShop/venv/lib/python3.9/site-packages/aiogram/bot/bot.py", line 110, in get_updates
    result = await self.request(api.Methods.GET_UPDATES, payload)
  File "/Users/sammuurr/PycharmProjects/GeekShop/venv/lib/python3.9/site-packages/aiogram/bot/base.py", line 231, in request
    return await api.make_request(await self.get_session(), self.server, self.__token, method, data, files,
  File "/Users/sammuurr/PycharmProjects/GeekShop/venv/lib/python3.9/site-packages/aiogram/bot/api.py", line 142, in make_request
    raise exceptions.NetworkError(f"aiohttp client throws an error: {e.__class__.__name__}: {e}")
aiogram.utils.exceptions.NetworkError: Aiohttp client throws an error: ClientConnectorError: Cannot connect to host api.telegram.org:443 ssl:default [nodename nor servname provided, or not known]
[2022-06-27 13:11:53,816] - [ERROR] -->  Cause exception while getting updates.
Traceback (most recent call last):
  File "/Users/sammuurr/PycharmProjects/GeekShop/venv/lib/python3.9/site-packages/aiohttp/connector.py", line 1154, in _create_direct_connection
    hosts = await asyncio.shield(host_resolved)
  File "/Users/sammuurr/PycharmProjects/GeekShop/venv/lib/python3.9/site-packages/aiohttp/connector.py", line 880, in _resolve_host
    addrs = await self._resolver.resolve(host, port, family=self._family)
  File "/Users/sammuurr/PycharmProjects/GeekShop/venv/lib/python3.9/site-packages/aiohttp/resolver.py", line 33, in resolve
    infos = await self._loop.getaddrinfo(
  File "/Library/Frameworks/Python.framework/Versions/3.9/lib/python3.9/asyncio/base_events.py", line 856, in getaddrinfo
    return await self.run_in_executor(
  File "/Library/Frameworks/Python.framework/Versions/3.9/lib/python3.9/concurrent/futures/thread.py", line 52, in run
    result = self.fn(*self.args, **self.kwargs)
  File "/Library/Frameworks/Python.framework/Versions/3.9/lib/python3.9/socket.py", line 953, in getaddrinfo
    for res in _socket.getaddrinfo(host, port, family, type, proto, flags):
socket.gaierror: [Errno 8] nodename nor servname provided, or not known

The above exception was the direct cause of the following exception:

Traceback (most recent call last):
  File "/Users/sammuurr/PycharmProjects/GeekShop/venv/lib/python3.9/site-packages/aiogram/bot/api.py", line 139, in make_request
    async with session.post(url, data=req, **kwargs) as response:
  File "/Users/sammuurr/PycharmProjects/GeekShop/venv/lib/python3.9/site-packages/aiohttp/client.py", line 1138, in __aenter__
    self._resp = await self._coro
  File "/Users/sammuurr/PycharmProjects/GeekShop/venv/lib/python3.9/site-packages/aiohttp/client.py", line 535, in _request
    conn = await self._connector.connect(
  File "/Users/sammuurr/PycharmProjects/GeekShop/venv/lib/python3.9/site-packages/aiohttp/connector.py", line 542, in connect
    proto = await self._create_connection(req, traces, timeout)
  File "/Users/sammuurr/PycharmProjects/GeekShop/venv/lib/python3.9/site-packages/aiohttp/connector.py", line 907, in _create_connection
    _, proto = await self._create_direct_connection(req, traces, timeout)
  File "/Users/sammuurr/PycharmProjects/GeekShop/venv/lib/python3.9/site-packages/aiohttp/connector.py", line 1166, in _create_direct_connection
    raise ClientConnectorError(req.connection_key, exc) from exc
aiohttp.client_exceptions.ClientConnectorError: Cannot connect to host api.telegram.org:443 ssl:default [nodename nor servname provided, or not known]

During handling of the above exception, another exception occurred:

Traceback (most recent call last):
  File "/Users/sammuurr/PycharmProjects/GeekShop/venv/lib/python3.9/site-packages/aiogram/dispatcher/dispatcher.py", line 381, in start_polling
    updates = await self.bot.get_updates(
  File "/Users/sammuurr/PycharmProjects/GeekShop/venv/lib/python3.9/site-packages/aiogram/bot/bot.py", line 110, in get_updates
    result = await self.request(api.Methods.GET_UPDATES, payload)
  File "/Users/sammuurr/PycharmProjects/GeekShop/venv/lib/python3.9/site-packages/aiogram/bot/base.py", line 231, in request
    return await api.make_request(await self.get_session(), self.server, self.__token, method, data, files,
  File "/Users/sammuurr/PycharmProjects/GeekShop/venv/lib/python3.9/site-packages/aiogram/bot/api.py", line 142, in make_request
    raise exceptions.NetworkError(f"aiohttp client throws an error: {e.__class__.__name__}: {e}")
aiogram.utils.exceptions.NetworkError: Aiohttp client throws an error: ClientConnectorError: Cannot connect to host api.telegram.org:443 ssl:default [nodename nor servname provided, or not known]
[2022-06-27 16:54:55,478] - [ERROR] -->  Cause exception while getting updates.
Traceback (most recent call last):
  File "/Users/sammuurr/PycharmProjects/GeekShop/venv/lib/python3.9/site-packages/aiogram/dispatcher/dispatcher.py", line 381, in start_polling
    updates = await self.bot.get_updates(
  File "/Users/sammuurr/PycharmProjects/GeekShop/venv/lib/python3.9/site-packages/aiogram/bot/bot.py", line 110, in get_updates
    result = await self.request(api.Methods.GET_UPDATES, payload)
  File "/Users/sammuurr/PycharmProjects/GeekShop/venv/lib/python3.9/site-packages/aiogram/bot/base.py", line 231, in request
    return await api.make_request(await self.get_session(), self.server, self.__token, method, data, files,
  File "/Users/sammuurr/PycharmProjects/GeekShop/venv/lib/python3.9/site-packages/aiogram/bot/api.py", line 139, in make_request
    async with session.post(url, data=req, **kwargs) as response:
  File "/Users/sammuurr/PycharmProjects/GeekShop/venv/lib/python3.9/site-packages/aiohttp/client.py", line 1138, in __aenter__
    self._resp = await self._coro
  File "/Users/sammuurr/PycharmProjects/GeekShop/venv/lib/python3.9/site-packages/aiohttp/client.py", line 559, in _request
    await resp.start(conn)
  File "/Users/sammuurr/PycharmProjects/GeekShop/venv/lib/python3.9/site-packages/aiohttp/client_reqrep.py", line 913, in start
    self._continue = None
  File "/Users/sammuurr/PycharmProjects/GeekShop/venv/lib/python3.9/site-packages/aiohttp/helpers.py", line 721, in __exit__
    raise asyncio.TimeoutError from None
asyncio.exceptions.TimeoutError
[2022-06-27 21:42:12,609] - [ERROR] -->  Cause exception while getting updates.
Traceback (most recent call last):
  File "/Users/sammuurr/PycharmProjects/GeekShop/venv/lib/python3.9/site-packages/aiogram/dispatcher/dispatcher.py", line 381, in start_polling
    updates = await self.bot.get_updates(
  File "/Users/sammuurr/PycharmProjects/GeekShop/venv/lib/python3.9/site-packages/aiogram/bot/bot.py", line 110, in get_updates
    result = await self.request(api.Methods.GET_UPDATES, payload)
  File "/Users/sammuurr/PycharmProjects/GeekShop/venv/lib/python3.9/site-packages/aiogram/bot/base.py", line 231, in request
    return await api.make_request(await self.get_session(), self.server, self.__token, method, data, files,
  File "/Users/sammuurr/PycharmProjects/GeekShop/venv/lib/python3.9/site-packages/aiogram/bot/api.py", line 139, in make_request
    async with session.post(url, data=req, **kwargs) as response:
  File "/Users/sammuurr/PycharmProjects/GeekShop/venv/lib/python3.9/site-packages/aiohttp/client.py", line 1138, in __aenter__
    self._resp = await self._coro
  File "/Users/sammuurr/PycharmProjects/GeekShop/venv/lib/python3.9/site-packages/aiohttp/client.py", line 559, in _request
    await resp.start(conn)
  File "/Users/sammuurr/PycharmProjects/GeekShop/venv/lib/python3.9/site-packages/aiohttp/client_reqrep.py", line 913, in start
    self._continue = None
  File "/Users/sammuurr/PycharmProjects/GeekShop/venv/lib/python3.9/site-packages/aiohttp/helpers.py", line 721, in __exit__
    raise asyncio.TimeoutError from None
asyncio.exceptions.TimeoutError
[2022-06-28 05:42:23,512] - [ERROR] -->  Cause exception while getting updates.
Traceback (most recent call last):
  File "/Users/sammuurr/PycharmProjects/GeekShop/venv/lib/python3.9/site-packages/aiogram/dispatcher/dispatcher.py", line 381, in start_polling
    updates = await self.bot.get_updates(
  File "/Users/sammuurr/PycharmProjects/GeekShop/venv/lib/python3.9/site-packages/aiogram/bot/bot.py", line 110, in get_updates
    result = await self.request(api.Methods.GET_UPDATES, payload)
  File "/Users/sammuurr/PycharmProjects/GeekShop/venv/lib/python3.9/site-packages/aiogram/bot/base.py", line 231, in request
    return await api.make_request(await self.get_session(), self.server, self.__token, method, data, files,
  File "/Users/sammuurr/PycharmProjects/GeekShop/venv/lib/python3.9/site-packages/aiogram/bot/api.py", line 139, in make_request
    async with session.post(url, data=req, **kwargs) as response:
  File "/Users/sammuurr/PycharmProjects/GeekShop/venv/lib/python3.9/site-packages/aiohttp/client.py", line 1138, in __aenter__
    self._resp = await self._coro
  File "/Users/sammuurr/PycharmProjects/GeekShop/venv/lib/python3.9/site-packages/aiohttp/client.py", line 559, in _request
    await resp.start(conn)
  File "/Users/sammuurr/PycharmProjects/GeekShop/venv/lib/python3.9/site-packages/aiohttp/client_reqrep.py", line 913, in start
    self._continue = None
  File "/Users/sammuurr/PycharmProjects/GeekShop/venv/lib/python3.9/site-packages/aiohttp/helpers.py", line 721, in __exit__
    raise asyncio.TimeoutError from None
asyncio.exceptions.TimeoutError
[2022-06-28 11:56:57,516] - [ERROR] -->  Cause exception while getting updates.
Traceback (most recent call last):
  File "/Users/sammuurr/PycharmProjects/GeekShop/venv/lib/python3.9/site-packages/aiogram/dispatcher/dispatcher.py", line 381, in start_polling
    updates = await self.bot.get_updates(
  File "/Users/sammuurr/PycharmProjects/GeekShop/venv/lib/python3.9/site-packages/aiogram/bot/bot.py", line 110, in get_updates
    result = await self.request(api.Methods.GET_UPDATES, payload)
  File "/Users/sammuurr/PycharmProjects/GeekShop/venv/lib/python3.9/site-packages/aiogram/bot/base.py", line 231, in request
    return await api.make_request(await self.get_session(), self.server, self.__token, method, data, files,
  File "/Users/sammuurr/PycharmProjects/GeekShop/venv/lib/python3.9/site-packages/aiogram/bot/api.py", line 139, in make_request
    async with session.post(url, data=req, **kwargs) as response:
  File "/Users/sammuurr/PycharmProjects/GeekShop/venv/lib/python3.9/site-packages/aiohttp/client.py", line 1138, in __aenter__
    self._resp = await self._coro
  File "/Users/sammuurr/PycharmProjects/GeekShop/venv/lib/python3.9/site-packages/aiohttp/client.py", line 559, in _request
    await resp.start(conn)
  File "/Users/sammuurr/PycharmProjects/GeekShop/venv/lib/python3.9/site-packages/aiohttp/client_reqrep.py", line 913, in start
    self._continue = None
  File "/Users/sammuurr/PycharmProjects/GeekShop/venv/lib/python3.9/site-packages/aiohttp/helpers.py", line 721, in __exit__
    raise asyncio.TimeoutError from None
asyncio.exceptions.TimeoutError
[2022-06-28 17:22:59,556] - [ERROR] -->  Cause exception while getting updates.
Traceback (most recent call last):
  File "/Users/sammuurr/PycharmProjects/GeekShop/venv/lib/python3.9/site-packages/aiogram/dispatcher/dispatcher.py", line 381, in start_polling
    updates = await self.bot.get_updates(
  File "/Users/sammuurr/PycharmProjects/GeekShop/venv/lib/python3.9/site-packages/aiogram/bot/bot.py", line 110, in get_updates
    result = await self.request(api.Methods.GET_UPDATES, payload)
  File "/Users/sammuurr/PycharmProjects/GeekShop/venv/lib/python3.9/site-packages/aiogram/bot/base.py", line 231, in request
    return await api.make_request(await self.get_session(), self.server, self.__token, method, data, files,
  File "/Users/sammuurr/PycharmProjects/GeekShop/venv/lib/python3.9/site-packages/aiogram/bot/api.py", line 139, in make_request
    async with session.post(url, data=req, **kwargs) as response:
  File "/Users/sammuurr/PycharmProjects/GeekShop/venv/lib/python3.9/site-packages/aiohttp/client.py", line 1138, in __aenter__
    self._resp = await self._coro
  File "/Users/sammuurr/PycharmProjects/GeekShop/venv/lib/python3.9/site-packages/aiohttp/client.py", line 559, in _request
    await resp.start(conn)
  File "/Users/sammuurr/PycharmProjects/GeekShop/venv/lib/python3.9/site-packages/aiohttp/client_reqrep.py", line 913, in start
    self._continue = None
  File "/Users/sammuurr/PycharmProjects/GeekShop/venv/lib/python3.9/site-packages/aiohttp/helpers.py", line 721, in __exit__
    raise asyncio.TimeoutError from None
asyncio.exceptions.TimeoutError
[2022-06-28 21:50:03,362] - [ERROR] -->  Cause exception while getting updates.
Traceback (most recent call last):
  File "/Users/sammuurr/PycharmProjects/GeekShop/venv/lib/python3.9/site-packages/aiogram/dispatcher/dispatcher.py", line 381, in start_polling
    updates = await self.bot.get_updates(
  File "/Users/sammuurr/PycharmProjects/GeekShop/venv/lib/python3.9/site-packages/aiogram/bot/bot.py", line 110, in get_updates
    result = await self.request(api.Methods.GET_UPDATES, payload)
  File "/Users/sammuurr/PycharmProjects/GeekShop/venv/lib/python3.9/site-packages/aiogram/bot/base.py", line 231, in request
    return await api.make_request(await self.get_session(), self.server, self.__token, method, data, files,
  File "/Users/sammuurr/PycharmProjects/GeekShop/venv/lib/python3.9/site-packages/aiogram/bot/api.py", line 139, in make_request
    async with session.post(url, data=req, **kwargs) as response:
  File "/Users/sammuurr/PycharmProjects/GeekShop/venv/lib/python3.9/site-packages/aiohttp/client.py", line 1138, in __aenter__
    self._resp = await self._coro
  File "/Users/sammuurr/PycharmProjects/GeekShop/venv/lib/python3.9/site-packages/aiohttp/client.py", line 559, in _request
    await resp.start(conn)
  File "/Users/sammuurr/PycharmProjects/GeekShop/venv/lib/python3.9/site-packages/aiohttp/client_reqrep.py", line 913, in start
    self._continue = None
  File "/Users/sammuurr/PycharmProjects/GeekShop/venv/lib/python3.9/site-packages/aiohttp/helpers.py", line 721, in __exit__
    raise asyncio.TimeoutError from None
asyncio.exceptions.TimeoutError
[2022-06-29 04:19:14,123] - [ERROR] -->  Cause exception while getting updates.
Traceback (most recent call last):
  File "/Users/sammuurr/PycharmProjects/GeekShop/venv/lib/python3.9/site-packages/aiogram/dispatcher/dispatcher.py", line 381, in start_polling
    updates = await self.bot.get_updates(
  File "/Users/sammuurr/PycharmProjects/GeekShop/venv/lib/python3.9/site-packages/aiogram/bot/bot.py", line 110, in get_updates
    result = await self.request(api.Methods.GET_UPDATES, payload)
  File "/Users/sammuurr/PycharmProjects/GeekShop/venv/lib/python3.9/site-packages/aiogram/bot/base.py", line 231, in request
    return await api.make_request(await self.get_session(), self.server, self.__token, method, data, files,
  File "/Users/sammuurr/PycharmProjects/GeekShop/venv/lib/python3.9/site-packages/aiogram/bot/api.py", line 139, in make_request
    async with session.post(url, data=req, **kwargs) as response:
  File "/Users/sammuurr/PycharmProjects/GeekShop/venv/lib/python3.9/site-packages/aiohttp/client.py", line 1138, in __aenter__
    self._resp = await self._coro
  File "/Users/sammuurr/PycharmProjects/GeekShop/venv/lib/python3.9/site-packages/aiohttp/client.py", line 559, in _request
    await resp.start(conn)
  File "/Users/sammuurr/PycharmProjects/GeekShop/venv/lib/python3.9/site-packages/aiohttp/client_reqrep.py", line 913, in start
    self._continue = None
  File "/Users/sammuurr/PycharmProjects/GeekShop/venv/lib/python3.9/site-packages/aiohttp/helpers.py", line 721, in __exit__
    raise asyncio.TimeoutError from None
asyncio.exceptions.TimeoutError
[2022-06-29 13:21:37,742] - [ERROR] -->  Cause exception while getting updates.
Traceback (most recent call last):
  File "/Users/sammuurr/PycharmProjects/GeekShop/venv/lib/python3.9/site-packages/aiogram/dispatcher/dispatcher.py", line 381, in start_polling
    updates = await self.bot.get_updates(
  File "/Users/sammuurr/PycharmProjects/GeekShop/venv/lib/python3.9/site-packages/aiogram/bot/bot.py", line 110, in get_updates
    result = await self.request(api.Methods.GET_UPDATES, payload)
  File "/Users/sammuurr/PycharmProjects/GeekShop/venv/lib/python3.9/site-packages/aiogram/bot/base.py", line 231, in request
    return await api.make_request(await self.get_session(), self.server, self.__token, method, data, files,
  File "/Users/sammuurr/PycharmProjects/GeekShop/venv/lib/python3.9/site-packages/aiogram/bot/api.py", line 139, in make_request
    async with session.post(url, data=req, **kwargs) as response:
  File "/Users/sammuurr/PycharmProjects/GeekShop/venv/lib/python3.9/site-packages/aiohttp/client.py", line 1138, in __aenter__
    self._resp = await self._coro
  File "/Users/sammuurr/PycharmProjects/GeekShop/venv/lib/python3.9/site-packages/aiohttp/client.py", line 559, in _request
    await resp.start(conn)
  File "/Users/sammuurr/PycharmProjects/GeekShop/venv/lib/python3.9/site-packages/aiohttp/client_reqrep.py", line 913, in start
    self._continue = None
  File "/Users/sammuurr/PycharmProjects/GeekShop/venv/lib/python3.9/site-packages/aiohttp/helpers.py", line 721, in __exit__
    raise asyncio.TimeoutError from None
asyncio.exceptions.TimeoutError
[2022-06-29 15:37:34,513] - [ERROR] -->  Cause exception while getting updates.
Traceback (most recent call last):
  File "/Users/sammuurr/PycharmProjects/GeekShop/venv/lib/python3.9/site-packages/aiogram/dispatcher/dispatcher.py", line 381, in start_polling
    updates = await self.bot.get_updates(
  File "/Users/sammuurr/PycharmProjects/GeekShop/venv/lib/python3.9/site-packages/aiogram/bot/bot.py", line 110, in get_updates
    result = await self.request(api.Methods.GET_UPDATES, payload)
  File "/Users/sammuurr/PycharmProjects/GeekShop/venv/lib/python3.9/site-packages/aiogram/bot/base.py", line 231, in request
    return await api.make_request(await self.get_session(), self.server, self.__token, method, data, files,
  File "/Users/sammuurr/PycharmProjects/GeekShop/venv/lib/python3.9/site-packages/aiogram/bot/api.py", line 139, in make_request
    async with session.post(url, data=req, **kwargs) as response:
  File "/Users/sammuurr/PycharmProjects/GeekShop/venv/lib/python3.9/site-packages/aiohttp/client.py", line 1138, in __aenter__
    self._resp = await self._coro
  File "/Users/sammuurr/PycharmProjects/GeekShop/venv/lib/python3.9/site-packages/aiohttp/client.py", line 559, in _request
    await resp.start(conn)
  File "/Users/sammuurr/PycharmProjects/GeekShop/venv/lib/python3.9/site-packages/aiohttp/client_reqrep.py", line 913, in start
    self._continue = None
  File "/Users/sammuurr/PycharmProjects/GeekShop/venv/lib/python3.9/site-packages/aiohttp/helpers.py", line 721, in __exit__
    raise asyncio.TimeoutError from None
asyncio.exceptions.TimeoutError
[2022-06-29 17:54:16,959] - [ERROR] -->  Cause exception while getting updates.
Traceback (most recent call last):
  File "/Users/sammuurr/PycharmProjects/GeekShop/venv/lib/python3.9/site-packages/aiogram/dispatcher/dispatcher.py", line 381, in start_polling
    updates = await self.bot.get_updates(
  File "/Users/sammuurr/PycharmProjects/GeekShop/venv/lib/python3.9/site-packages/aiogram/bot/bot.py", line 110, in get_updates
    result = await self.request(api.Methods.GET_UPDATES, payload)
  File "/Users/sammuurr/PycharmProjects/GeekShop/venv/lib/python3.9/site-packages/aiogram/bot/base.py", line 231, in request
    return await api.make_request(await self.get_session(), self.server, self.__token, method, data, files,
  File "/Users/sammuurr/PycharmProjects/GeekShop/venv/lib/python3.9/site-packages/aiogram/bot/api.py", line 139, in make_request
    async with session.post(url, data=req, **kwargs) as response:
  File "/Users/sammuurr/PycharmProjects/GeekShop/venv/lib/python3.9/site-packages/aiohttp/client.py", line 1138, in __aenter__
    self._resp = await self._coro
  File "/Users/sammuurr/PycharmProjects/GeekShop/venv/lib/python3.9/site-packages/aiohttp/client.py", line 559, in _request
    await resp.start(conn)
  File "/Users/sammuurr/PycharmProjects/GeekShop/venv/lib/python3.9/site-packages/aiohttp/client_reqrep.py", line 913, in start
    self._continue = None
  File "/Users/sammuurr/PycharmProjects/GeekShop/venv/lib/python3.9/site-packages/aiohttp/helpers.py", line 721, in __exit__
    raise asyncio.TimeoutError from None
asyncio.exceptions.TimeoutError
[2022-06-29 18:04:40,922] - [ERROR] -->  Cause exception while getting updates.
Traceback (most recent call last):
  File "/Users/sammuurr/PycharmProjects/GeekShop/venv/lib/python3.9/site-packages/aiogram/dispatcher/dispatcher.py", line 381, in start_polling
    updates = await self.bot.get_updates(
  File "/Users/sammuurr/PycharmProjects/GeekShop/venv/lib/python3.9/site-packages/aiogram/bot/bot.py", line 110, in get_updates
    result = await self.request(api.Methods.GET_UPDATES, payload)
  File "/Users/sammuurr/PycharmProjects/GeekShop/venv/lib/python3.9/site-packages/aiogram/bot/base.py", line 231, in request
    return await api.make_request(await self.get_session(), self.server, self.__token, method, data, files,
  File "/Users/sammuurr/PycharmProjects/GeekShop/venv/lib/python3.9/site-packages/aiogram/bot/api.py", line 139, in make_request
    async with session.post(url, data=req, **kwargs) as response:
  File "/Users/sammuurr/PycharmProjects/GeekShop/venv/lib/python3.9/site-packages/aiohttp/client.py", line 1138, in __aenter__
    self._resp = await self._coro
  File "/Users/sammuurr/PycharmProjects/GeekShop/venv/lib/python3.9/site-packages/aiohttp/client.py", line 559, in _request
    await resp.start(conn)
  File "/Users/sammuurr/PycharmProjects/GeekShop/venv/lib/python3.9/site-packages/aiohttp/client_reqrep.py", line 913, in start
    self._continue = None
  File "/Users/sammuurr/PycharmProjects/GeekShop/venv/lib/python3.9/site-packages/aiohttp/helpers.py", line 721, in __exit__
    raise asyncio.TimeoutError from None
asyncio.exceptions.TimeoutError
[2022-06-29 23:17:20,222] - [ERROR] -->  Cause exception while getting updates.
Traceback (most recent call last):
  File "/Users/sammuurr/PycharmProjects/GeekShop/venv/lib/python3.9/site-packages/aiogram/dispatcher/dispatcher.py", line 381, in start_polling
    updates = await self.bot.get_updates(
  File "/Users/sammuurr/PycharmProjects/GeekShop/venv/lib/python3.9/site-packages/aiogram/bot/bot.py", line 110, in get_updates
    result = await self.request(api.Methods.GET_UPDATES, payload)
  File "/Users/sammuurr/PycharmProjects/GeekShop/venv/lib/python3.9/site-packages/aiogram/bot/base.py", line 231, in request
    return await api.make_request(await self.get_session(), self.server, self.__token, method, data, files,
  File "/Users/sammuurr/PycharmProjects/GeekShop/venv/lib/python3.9/site-packages/aiogram/bot/api.py", line 139, in make_request
    async with session.post(url, data=req, **kwargs) as response:
  File "/Users/sammuurr/PycharmProjects/GeekShop/venv/lib/python3.9/site-packages/aiohttp/client.py", line 1138, in __aenter__
    self._resp = await self._coro
  File "/Users/sammuurr/PycharmProjects/GeekShop/venv/lib/python3.9/site-packages/aiohttp/client.py", line 559, in _request
    await resp.start(conn)
  File "/Users/sammuurr/PycharmProjects/GeekShop/venv/lib/python3.9/site-packages/aiohttp/client_reqrep.py", line 913, in start
    self._continue = None
  File "/Users/sammuurr/PycharmProjects/GeekShop/venv/lib/python3.9/site-packages/aiohttp/helpers.py", line 721, in __exit__
    raise asyncio.TimeoutError from None
asyncio.exceptions.TimeoutError
[2022-06-30 01:05:59,075] - [ERROR] -->  Cause exception while getting updates.
Traceback (most recent call last):
  File "/Users/sammuurr/PycharmProjects/GeekShop/venv/lib/python3.9/site-packages/aiogram/dispatcher/dispatcher.py", line 381, in start_polling
    updates = await self.bot.get_updates(
  File "/Users/sammuurr/PycharmProjects/GeekShop/venv/lib/python3.9/site-packages/aiogram/bot/bot.py", line 110, in get_updates
    result = await self.request(api.Methods.GET_UPDATES, payload)
  File "/Users/sammuurr/PycharmProjects/GeekShop/venv/lib/python3.9/site-packages/aiogram/bot/base.py", line 231, in request
    return await api.make_request(await self.get_session(), self.server, self.__token, method, data, files,
  File "/Users/sammuurr/PycharmProjects/GeekShop/venv/lib/python3.9/site-packages/aiogram/bot/api.py", line 139, in make_request
    async with session.post(url, data=req, **kwargs) as response:
  File "/Users/sammuurr/PycharmProjects/GeekShop/venv/lib/python3.9/site-packages/aiohttp/client.py", line 1138, in __aenter__
    self._resp = await self._coro
  File "/Users/sammuurr/PycharmProjects/GeekShop/venv/lib/python3.9/site-packages/aiohttp/client.py", line 559, in _request
    await resp.start(conn)
  File "/Users/sammuurr/PycharmProjects/GeekShop/venv/lib/python3.9/site-packages/aiohttp/client_reqrep.py", line 913, in start
    self._continue = None
  File "/Users/sammuurr/PycharmProjects/GeekShop/venv/lib/python3.9/site-packages/aiohttp/helpers.py", line 721, in __exit__
    raise asyncio.TimeoutError from None
asyncio.exceptions.TimeoutError
[2022-06-30 01:20:36,059] - [ERROR] -->  Cause exception while getting updates.
Traceback (most recent call last):
  File "/Users/sammuurr/PycharmProjects/GeekShop/venv/lib/python3.9/site-packages/aiogram/dispatcher/dispatcher.py", line 381, in start_polling
    updates = await self.bot.get_updates(
  File "/Users/sammuurr/PycharmProjects/GeekShop/venv/lib/python3.9/site-packages/aiogram/bot/bot.py", line 110, in get_updates
    result = await self.request(api.Methods.GET_UPDATES, payload)
  File "/Users/sammuurr/PycharmProjects/GeekShop/venv/lib/python3.9/site-packages/aiogram/bot/base.py", line 231, in request
    return await api.make_request(await self.get_session(), self.server, self.__token, method, data, files,
  File "/Users/sammuurr/PycharmProjects/GeekShop/venv/lib/python3.9/site-packages/aiogram/bot/api.py", line 139, in make_request
    async with session.post(url, data=req, **kwargs) as response:
  File "/Users/sammuurr/PycharmProjects/GeekShop/venv/lib/python3.9/site-packages/aiohttp/client.py", line 1138, in __aenter__
    self._resp = await self._coro
  File "/Users/sammuurr/PycharmProjects/GeekShop/venv/lib/python3.9/site-packages/aiohttp/client.py", line 559, in _request
    await resp.start(conn)
  File "/Users/sammuurr/PycharmProjects/GeekShop/venv/lib/python3.9/site-packages/aiohttp/client_reqrep.py", line 913, in start
    self._continue = None
  File "/Users/sammuurr/PycharmProjects/GeekShop/venv/lib/python3.9/site-packages/aiohttp/helpers.py", line 721, in __exit__
    raise asyncio.TimeoutError from None
asyncio.exceptions.TimeoutError
[2022-06-30 05:36:48,061] - [ERROR] -->  Cause exception while getting updates.
Traceback (most recent call last):
  File "/Users/sammuurr/PycharmProjects/GeekShop/venv/lib/python3.9/site-packages/aiogram/dispatcher/dispatcher.py", line 381, in start_polling
    updates = await self.bot.get_updates(
  File "/Users/sammuurr/PycharmProjects/GeekShop/venv/lib/python3.9/site-packages/aiogram/bot/bot.py", line 110, in get_updates
    result = await self.request(api.Methods.GET_UPDATES, payload)
  File "/Users/sammuurr/PycharmProjects/GeekShop/venv/lib/python3.9/site-packages/aiogram/bot/base.py", line 231, in request
    return await api.make_request(await self.get_session(), self.server, self.__token, method, data, files,
  File "/Users/sammuurr/PycharmProjects/GeekShop/venv/lib/python3.9/site-packages/aiogram/bot/api.py", line 139, in make_request
    async with session.post(url, data=req, **kwargs) as response:
  File "/Users/sammuurr/PycharmProjects/GeekShop/venv/lib/python3.9/site-packages/aiohttp/client.py", line 1138, in __aenter__
    self._resp = await self._coro
  File "/Users/sammuurr/PycharmProjects/GeekShop/venv/lib/python3.9/site-packages/aiohttp/client.py", line 559, in _request
    await resp.start(conn)
  File "/Users/sammuurr/PycharmProjects/GeekShop/venv/lib/python3.9/site-packages/aiohttp/client_reqrep.py", line 913, in start
    self._continue = None
  File "/Users/sammuurr/PycharmProjects/GeekShop/venv/lib/python3.9/site-packages/aiohttp/helpers.py", line 721, in __exit__
    raise asyncio.TimeoutError from None
asyncio.exceptions.TimeoutError
[2022-06-30 10:53:02,631] - [ERROR] -->  Cause exception while getting updates.
Traceback (most recent call last):
  File "/Users/sammuurr/PycharmProjects/GeekShop/venv/lib/python3.9/site-packages/aiogram/dispatcher/dispatcher.py", line 381, in start_polling
    updates = await self.bot.get_updates(
  File "/Users/sammuurr/PycharmProjects/GeekShop/venv/lib/python3.9/site-packages/aiogram/bot/bot.py", line 110, in get_updates
    result = await self.request(api.Methods.GET_UPDATES, payload)
  File "/Users/sammuurr/PycharmProjects/GeekShop/venv/lib/python3.9/site-packages/aiogram/bot/base.py", line 231, in request
    return await api.make_request(await self.get_session(), self.server, self.__token, method, data, files,
  File "/Users/sammuurr/PycharmProjects/GeekShop/venv/lib/python3.9/site-packages/aiogram/bot/api.py", line 139, in make_request
    async with session.post(url, data=req, **kwargs) as response:
  File "/Users/sammuurr/PycharmProjects/GeekShop/venv/lib/python3.9/site-packages/aiohttp/client.py", line 1138, in __aenter__
    self._resp = await self._coro
  File "/Users/sammuurr/PycharmProjects/GeekShop/venv/lib/python3.9/site-packages/aiohttp/client.py", line 559, in _request
    await resp.start(conn)
  File "/Users/sammuurr/PycharmProjects/GeekShop/venv/lib/python3.9/site-packages/aiohttp/client_reqrep.py", line 913, in start
    self._continue = None
  File "/Users/sammuurr/PycharmProjects/GeekShop/venv/lib/python3.9/site-packages/aiohttp/helpers.py", line 721, in __exit__
    raise asyncio.TimeoutError from None
asyncio.exceptions.TimeoutError
[2022-07-02 13:51:00,163] - [ERROR] -->  Cause exception while getting updates.
Traceback (most recent call last):
  File "/Users/sammuurr/PycharmProjects/GeekShop/venv/lib/python3.9/site-packages/aiogram/dispatcher/dispatcher.py", line 381, in start_polling
    updates = await self.bot.get_updates(
  File "/Users/sammuurr/PycharmProjects/GeekShop/venv/lib/python3.9/site-packages/aiogram/bot/bot.py", line 110, in get_updates
    result = await self.request(api.Methods.GET_UPDATES, payload)
  File "/Users/sammuurr/PycharmProjects/GeekShop/venv/lib/python3.9/site-packages/aiogram/bot/base.py", line 231, in request
    return await api.make_request(await self.get_session(), self.server, self.__token, method, data, files,
  File "/Users/sammuurr/PycharmProjects/GeekShop/venv/lib/python3.9/site-packages/aiogram/bot/api.py", line 139, in make_request
    async with session.post(url, data=req, **kwargs) as response:
  File "/Users/sammuurr/PycharmProjects/GeekShop/venv/lib/python3.9/site-packages/aiohttp/client.py", line 1138, in __aenter__
    self._resp = await self._coro
  File "/Users/sammuurr/PycharmProjects/GeekShop/venv/lib/python3.9/site-packages/aiohttp/client.py", line 559, in _request
    await resp.start(conn)
  File "/Users/sammuurr/PycharmProjects/GeekShop/venv/lib/python3.9/site-packages/aiohttp/client_reqrep.py", line 913, in start
    self._continue = None
  File "/Users/sammuurr/PycharmProjects/GeekShop/venv/lib/python3.9/site-packages/aiohttp/helpers.py", line 721, in __exit__
    raise asyncio.TimeoutError from None
asyncio.exceptions.TimeoutError
[2022-07-02 19:08:44,550] - [ERROR] -->  Cause exception while getting updates.
Traceback (most recent call last):
  File "/Users/sammuurr/PycharmProjects/GeekShop/venv/lib/python3.9/site-packages/aiogram/dispatcher/dispatcher.py", line 381, in start_polling
    updates = await self.bot.get_updates(
  File "/Users/sammuurr/PycharmProjects/GeekShop/venv/lib/python3.9/site-packages/aiogram/bot/bot.py", line 110, in get_updates
    result = await self.request(api.Methods.GET_UPDATES, payload)
  File "/Users/sammuurr/PycharmProjects/GeekShop/venv/lib/python3.9/site-packages/aiogram/bot/base.py", line 231, in request
    return await api.make_request(await self.get_session(), self.server, self.__token, method, data, files,
  File "/Users/sammuurr/PycharmProjects/GeekShop/venv/lib/python3.9/site-packages/aiogram/bot/api.py", line 139, in make_request
    async with session.post(url, data=req, **kwargs) as response:
  File "/Users/sammuurr/PycharmProjects/GeekShop/venv/lib/python3.9/site-packages/aiohttp/client.py", line 1138, in __aenter__
    self._resp = await self._coro
  File "/Users/sammuurr/PycharmProjects/GeekShop/venv/lib/python3.9/site-packages/aiohttp/client.py", line 559, in _request
    await resp.start(conn)
  File "/Users/sammuurr/PycharmProjects/GeekShop/venv/lib/python3.9/site-packages/aiohttp/client_reqrep.py", line 913, in start
    self._continue = None
  File "/Users/sammuurr/PycharmProjects/GeekShop/venv/lib/python3.9/site-packages/aiohttp/helpers.py", line 721, in __exit__
    raise asyncio.TimeoutError from None
asyncio.exceptions.TimeoutError
[2022-07-03 01:53:02,409] - [ERROR] -->  Cause exception while getting updates.
Traceback (most recent call last):
  File "/Users/sammuurr/PycharmProjects/GeekShop/venv/lib/python3.9/site-packages/aiogram/dispatcher/dispatcher.py", line 381, in start_polling
    updates = await self.bot.get_updates(
  File "/Users/sammuurr/PycharmProjects/GeekShop/venv/lib/python3.9/site-packages/aiogram/bot/bot.py", line 110, in get_updates
    result = await self.request(api.Methods.GET_UPDATES, payload)
  File "/Users/sammuurr/PycharmProjects/GeekShop/venv/lib/python3.9/site-packages/aiogram/bot/base.py", line 231, in request
    return await api.make_request(await self.get_session(), self.server, self.__token, method, data, files,
  File "/Users/sammuurr/PycharmProjects/GeekShop/venv/lib/python3.9/site-packages/aiogram/bot/api.py", line 139, in make_request
    async with session.post(url, data=req, **kwargs) as response:
  File "/Users/sammuurr/PycharmProjects/GeekShop/venv/lib/python3.9/site-packages/aiohttp/client.py", line 1138, in __aenter__
    self._resp = await self._coro
  File "/Users/sammuurr/PycharmProjects/GeekShop/venv/lib/python3.9/site-packages/aiohttp/client.py", line 559, in _request
    await resp.start(conn)
  File "/Users/sammuurr/PycharmProjects/GeekShop/venv/lib/python3.9/site-packages/aiohttp/client_reqrep.py", line 913, in start
    self._continue = None
  File "/Users/sammuurr/PycharmProjects/GeekShop/venv/lib/python3.9/site-packages/aiohttp/helpers.py", line 721, in __exit__
    raise asyncio.TimeoutError from None
asyncio.exceptions.TimeoutError
[2022-07-03 02:40:27,011] - [ERROR] -->  Cause exception while getting updates.
Traceback (most recent call last):
  File "/Users/sammuurr/PycharmProjects/GeekShop/venv/lib/python3.9/site-packages/aiogram/bot/api.py", line 139, in make_request
    async with session.post(url, data=req, **kwargs) as response:
  File "/Users/sammuurr/PycharmProjects/GeekShop/venv/lib/python3.9/site-packages/aiohttp/client.py", line 1138, in __aenter__
    self._resp = await self._coro
  File "/Users/sammuurr/PycharmProjects/GeekShop/venv/lib/python3.9/site-packages/aiohttp/client.py", line 559, in _request
    await resp.start(conn)
  File "/Users/sammuurr/PycharmProjects/GeekShop/venv/lib/python3.9/site-packages/aiohttp/client_reqrep.py", line 898, in start
    message, payload = await protocol.read()  # type: ignore[union-attr]
  File "/Users/sammuurr/PycharmProjects/GeekShop/venv/lib/python3.9/site-packages/aiohttp/streams.py", line 616, in read
    await self._waiter
aiohttp.client_exceptions.ClientOSError: [Errno 60] Operation timed out

During handling of the above exception, another exception occurred:

Traceback (most recent call last):
  File "/Users/sammuurr/PycharmProjects/GeekShop/venv/lib/python3.9/site-packages/aiogram/dispatcher/dispatcher.py", line 381, in start_polling
    updates = await self.bot.get_updates(
  File "/Users/sammuurr/PycharmProjects/GeekShop/venv/lib/python3.9/site-packages/aiogram/bot/bot.py", line 110, in get_updates
    result = await self.request(api.Methods.GET_UPDATES, payload)
  File "/Users/sammuurr/PycharmProjects/GeekShop/venv/lib/python3.9/site-packages/aiogram/bot/base.py", line 231, in request
    return await api.make_request(await self.get_session(), self.server, self.__token, method, data, files,
  File "/Users/sammuurr/PycharmProjects/GeekShop/venv/lib/python3.9/site-packages/aiogram/bot/api.py", line 142, in make_request
    raise exceptions.NetworkError(f"aiohttp client throws an error: {e.__class__.__name__}: {e}")
aiogram.utils.exceptions.NetworkError: Aiohttp client throws an error: ClientOSError: [Errno 60] Operation timed out
[2022-07-03 10:45:27,173] - [ERROR] -->  Cause exception while getting updates.
Traceback (most recent call last):
  File "/Users/sammuurr/PycharmProjects/GeekShop/venv/lib/python3.9/site-packages/aiogram/dispatcher/dispatcher.py", line 381, in start_polling
    updates = await self.bot.get_updates(
  File "/Users/sammuurr/PycharmProjects/GeekShop/venv/lib/python3.9/site-packages/aiogram/bot/bot.py", line 110, in get_updates
    result = await self.request(api.Methods.GET_UPDATES, payload)
  File "/Users/sammuurr/PycharmProjects/GeekShop/venv/lib/python3.9/site-packages/aiogram/bot/base.py", line 231, in request
    return await api.make_request(await self.get_session(), self.server, self.__token, method, data, files,
  File "/Users/sammuurr/PycharmProjects/GeekShop/venv/lib/python3.9/site-packages/aiogram/bot/api.py", line 139, in make_request
    async with session.post(url, data=req, **kwargs) as response:
  File "/Users/sammuurr/PycharmProjects/GeekShop/venv/lib/python3.9/site-packages/aiohttp/client.py", line 1138, in __aenter__
    self._resp = await self._coro
  File "/Users/sammuurr/PycharmProjects/GeekShop/venv/lib/python3.9/site-packages/aiohttp/client.py", line 559, in _request
    await resp.start(conn)
  File "/Users/sammuurr/PycharmProjects/GeekShop/venv/lib/python3.9/site-packages/aiohttp/client_reqrep.py", line 913, in start
    self._continue = None
  File "/Users/sammuurr/PycharmProjects/GeekShop/venv/lib/python3.9/site-packages/aiohttp/helpers.py", line 721, in __exit__
    raise asyncio.TimeoutError from None
asyncio.exceptions.TimeoutError
[2022-07-03 11:02:36,216] - [ERROR] -->  Cause exception while getting updates.
Traceback (most recent call last):
  File "/Users/sammuurr/PycharmProjects/GeekShop/venv/lib/python3.9/site-packages/aiogram/dispatcher/dispatcher.py", line 381, in start_polling
    updates = await self.bot.get_updates(
  File "/Users/sammuurr/PycharmProjects/GeekShop/venv/lib/python3.9/site-packages/aiogram/bot/bot.py", line 110, in get_updates
    result = await self.request(api.Methods.GET_UPDATES, payload)
  File "/Users/sammuurr/PycharmProjects/GeekShop/venv/lib/python3.9/site-packages/aiogram/bot/base.py", line 231, in request
    return await api.make_request(await self.get_session(), self.server, self.__token, method, data, files,
  File "/Users/sammuurr/PycharmProjects/GeekShop/venv/lib/python3.9/site-packages/aiogram/bot/api.py", line 139, in make_request
    async with session.post(url, data=req, **kwargs) as response:
  File "/Users/sammuurr/PycharmProjects/GeekShop/venv/lib/python3.9/site-packages/aiohttp/client.py", line 1138, in __aenter__
    self._resp = await self._coro
  File "/Users/sammuurr/PycharmProjects/GeekShop/venv/lib/python3.9/site-packages/aiohttp/client.py", line 559, in _request
    await resp.start(conn)
  File "/Users/sammuurr/PycharmProjects/GeekShop/venv/lib/python3.9/site-packages/aiohttp/client_reqrep.py", line 913, in start
    self._continue = None
  File "/Users/sammuurr/PycharmProjects/GeekShop/venv/lib/python3.9/site-packages/aiohttp/helpers.py", line 721, in __exit__
    raise asyncio.TimeoutError from None
asyncio.exceptions.TimeoutError
[2022-07-03 11:31:25,034] - [ERROR] -->  Cause exception while getting updates.
Traceback (most recent call last):
  File "/Users/sammuurr/PycharmProjects/GeekShop/venv/lib/python3.9/site-packages/aiogram/dispatcher/dispatcher.py", line 381, in start_polling
    updates = await self.bot.get_updates(
  File "/Users/sammuurr/PycharmProjects/GeekShop/venv/lib/python3.9/site-packages/aiogram/bot/bot.py", line 110, in get_updates
    result = await self.request(api.Methods.GET_UPDATES, payload)
  File "/Users/sammuurr/PycharmProjects/GeekShop/venv/lib/python3.9/site-packages/aiogram/bot/base.py", line 231, in request
    return await api.make_request(await self.get_session(), self.server, self.__token, method, data, files,
  File "/Users/sammuurr/PycharmProjects/GeekShop/venv/lib/python3.9/site-packages/aiogram/bot/api.py", line 139, in make_request
    async with session.post(url, data=req, **kwargs) as response:
  File "/Users/sammuurr/PycharmProjects/GeekShop/venv/lib/python3.9/site-packages/aiohttp/client.py", line 1138, in __aenter__
    self._resp = await self._coro
  File "/Users/sammuurr/PycharmProjects/GeekShop/venv/lib/python3.9/site-packages/aiohttp/client.py", line 559, in _request
    await resp.start(conn)
  File "/Users/sammuurr/PycharmProjects/GeekShop/venv/lib/python3.9/site-packages/aiohttp/client_reqrep.py", line 913, in start
    self._continue = None
  File "/Users/sammuurr/PycharmProjects/GeekShop/venv/lib/python3.9/site-packages/aiohttp/helpers.py", line 721, in __exit__
    raise asyncio.TimeoutError from None
asyncio.exceptions.TimeoutError
[2022-07-03 11:43:05,989] - [WARNING] -->  Goodbye!
[2022-07-03 11:46:18,915] - [WARNING] -->  Goodbye!
[2022-07-03 12:01:59,665] - [WARNING] -->  Goodbye!
[2022-07-03 12:24:15,845] - [WARNING] -->  Goodbye!
[2022-07-03 12:25:07,200] - [ERROR] -->  Task exception was never retrieved
future: <Task finished name='Task-35' coro=<Dispatcher._process_polling_updates() done, defined at /Users/sammuurr/PycharmProjects/GeekShop/venv/lib/python3.9/site-packages/aiogram/dispatcher/dispatcher.py:407> exception=TypeError("process_finish_state() missing 2 required positional arguments: 'message' and 'state'")>
Traceback (most recent call last):
  File "/Users/sammuurr/PycharmProjects/GeekShop/venv/lib/python3.9/site-packages/aiogram/dispatcher/dispatcher.py", line 415, in _process_polling_updates
    for responses in itertools.chain.from_iterable(await self.process_updates(updates, fast)):
  File "/Users/sammuurr/PycharmProjects/GeekShop/venv/lib/python3.9/site-packages/aiogram/dispatcher/dispatcher.py", line 235, in process_updates
    return await asyncio.gather(*tasks)
  File "/Users/sammuurr/PycharmProjects/GeekShop/venv/lib/python3.9/site-packages/aiogram/dispatcher/handler.py", line 116, in notify
    response = await handler_obj.handler(*args, **partial_data)
  File "/Users/sammuurr/PycharmProjects/GeekShop/venv/lib/python3.9/site-packages/aiogram/dispatcher/dispatcher.py", line 256, in process_update
    return await self.message_handlers.notify(update.message)
  File "/Users/sammuurr/PycharmProjects/GeekShop/venv/lib/python3.9/site-packages/aiogram/dispatcher/handler.py", line 116, in notify
    response = await handler_obj.handler(*args, **partial_data)
  File "/Users/sammuurr/PycharmProjects/GeekShop/handlers/text_handlers/main_menu/buyBot/sum.py", line 23, in sum
    return await process_finish_state()
TypeError: process_finish_state() missing 2 required positional arguments: 'message' and 'state'
[2022-07-03 12:27:26,630] - [WARNING] -->  Goodbye!
[2022-07-03 13:13:57,802] - [WARNING] -->  Goodbye!
[2022-07-03 13:15:03,087] - [WARNING] -->  Goodbye!
[2022-07-03 13:16:09,633] - [WARNING] -->  Goodbye!
[2022-07-03 13:17:06,762] - [WARNING] -->  Goodbye!
[2022-07-03 13:22:23,367] - [ERROR] -->  Cause exception while getting updates.
Traceback (most recent call last):
  File "/Users/sammuurr/PycharmProjects/GeekShop/venv/lib/python3.9/site-packages/aiogram/dispatcher/dispatcher.py", line 381, in start_polling
    updates = await self.bot.get_updates(
  File "/Users/sammuurr/PycharmProjects/GeekShop/venv/lib/python3.9/site-packages/aiogram/bot/bot.py", line 110, in get_updates
    result = await self.request(api.Methods.GET_UPDATES, payload)
  File "/Users/sammuurr/PycharmProjects/GeekShop/venv/lib/python3.9/site-packages/aiogram/bot/base.py", line 231, in request
    return await api.make_request(await self.get_session(), self.server, self.__token, method, data, files,
  File "/Users/sammuurr/PycharmProjects/GeekShop/venv/lib/python3.9/site-packages/aiogram/bot/api.py", line 139, in make_request
    async with session.post(url, data=req, **kwargs) as response:
  File "/Users/sammuurr/PycharmProjects/GeekShop/venv/lib/python3.9/site-packages/aiohttp/client.py", line 1138, in __aenter__
    self._resp = await self._coro
  File "/Users/sammuurr/PycharmProjects/GeekShop/venv/lib/python3.9/site-packages/aiohttp/client.py", line 559, in _request
    await resp.start(conn)
  File "/Users/sammuurr/PycharmProjects/GeekShop/venv/lib/python3.9/site-packages/aiohttp/client_reqrep.py", line 913, in start
    self._continue = None
  File "/Users/sammuurr/PycharmProjects/GeekShop/venv/lib/python3.9/site-packages/aiohttp/helpers.py", line 721, in __exit__
    raise asyncio.TimeoutError from None
asyncio.exceptions.TimeoutError
[2022-07-03 13:32:19,379] - [WARNING] -->  Goodbye!
[2022-07-03 13:33:12,872] - [WARNING] -->  Goodbye!
[2022-07-03 13:43:51,872] - [WARNING] -->  Goodbye!
[2022-07-03 13:46:16,291] - [WARNING] -->  Goodbye!
[2022-07-03 13:46:40,251] - [ERROR] -->  Task exception was never retrieved
future: <Task finished name='Task-8' coro=<Dispatcher._process_polling_updates() done, defined at /Users/sammuurr/PycharmProjects/GeekShop/venv/lib/python3.9/site-packages/aiogram/dispatcher/dispatcher.py:407> exception=TypeError("unsupported operand type(s) for +: 'Chat' and 'str'")>
Traceback (most recent call last):
  File "/Users/sammuurr/PycharmProjects/GeekShop/venv/lib/python3.9/site-packages/aiogram/dispatcher/dispatcher.py", line 415, in _process_polling_updates
    for responses in itertools.chain.from_iterable(await self.process_updates(updates, fast)):
  File "/Users/sammuurr/PycharmProjects/GeekShop/venv/lib/python3.9/site-packages/aiogram/dispatcher/dispatcher.py", line 235, in process_updates
    return await asyncio.gather(*tasks)
  File "/Users/sammuurr/PycharmProjects/GeekShop/venv/lib/python3.9/site-packages/aiogram/dispatcher/handler.py", line 116, in notify
    response = await handler_obj.handler(*args, **partial_data)
  File "/Users/sammuurr/PycharmProjects/GeekShop/venv/lib/python3.9/site-packages/aiogram/dispatcher/dispatcher.py", line 256, in process_update
    return await self.message_handlers.notify(update.message)
  File "/Users/sammuurr/PycharmProjects/GeekShop/venv/lib/python3.9/site-packages/aiogram/dispatcher/handler.py", line 116, in notify
    response = await handler_obj.handler(*args, **partial_data)
  File "/Users/sammuurr/PycharmProjects/GeekShop/handlers/text_handlers/main_menu/question.py", line 30, in process_question_request
    print(message.chat + "    " + admin_chat)
TypeError: unsupported operand type(s) for +: 'Chat' and 'str'
[2022-07-03 13:46:43,822] - [ERROR] -->  Task exception was never retrieved
future: <Task finished name='Task-11' coro=<Dispatcher._process_polling_updates() done, defined at /Users/sammuurr/PycharmProjects/GeekShop/venv/lib/python3.9/site-packages/aiogram/dispatcher/dispatcher.py:407> exception=AttributeError("'NoneType' object has no attribute 'id'")>
Traceback (most recent call last):
  File "/Users/sammuurr/PycharmProjects/GeekShop/venv/lib/python3.9/site-packages/aiogram/dispatcher/dispatcher.py", line 415, in _process_polling_updates
    for responses in itertools.chain.from_iterable(await self.process_updates(updates, fast)):
  File "/Users/sammuurr/PycharmProjects/GeekShop/venv/lib/python3.9/site-packages/aiogram/dispatcher/dispatcher.py", line 235, in process_updates
    return await asyncio.gather(*tasks)
  File "/Users/sammuurr/PycharmProjects/GeekShop/venv/lib/python3.9/site-packages/aiogram/dispatcher/handler.py", line 116, in notify
    response = await handler_obj.handler(*args, **partial_data)
  File "/Users/sammuurr/PycharmProjects/GeekShop/venv/lib/python3.9/site-packages/aiogram/dispatcher/dispatcher.py", line 256, in process_update
    return await self.message_handlers.notify(update.message)
  File "/Users/sammuurr/PycharmProjects/GeekShop/venv/lib/python3.9/site-packages/aiogram/dispatcher/handler.py", line 116, in notify
    response = await handler_obj.handler(*args, **partial_data)
  File "/Users/sammuurr/PycharmProjects/GeekShop/handlers/text_handlers/main_menu/question.py", line 29, in process_question_request
    print(message.reply_to_message.forward_from.id)
AttributeError: 'NoneType' object has no attribute 'id'
[2022-07-03 13:47:12,693] - [WARNING] -->  Goodbye!
[2022-07-03 13:48:57,107] - [WARNING] -->  Goodbye!
[2022-07-03 13:51:23,075] - [WARNING] -->  Goodbye!
[2022-07-03 13:52:32,220] - [WARNING] -->  Goodbye!
[2022-07-03 13:52:55,475] - [WARNING] -->  Goodbye!
[2022-07-03 13:53:17,225] - [ERROR] -->  Task exception was never retrieved
future: <Task finished name='Task-12' coro=<Dispatcher._process_polling_updates() done, defined at /Users/sammuurr/PycharmProjects/GeekShop/venv/lib/python3.9/site-packages/aiogram/dispatcher/dispatcher.py:407> exception=AttributeError("'NoneType' object has no attribute 'forward_from'")>
Traceback (most recent call last):
  File "/Users/sammuurr/PycharmProjects/GeekShop/venv/lib/python3.9/site-packages/aiogram/dispatcher/dispatcher.py", line 415, in _process_polling_updates
    for responses in itertools.chain.from_iterable(await self.process_updates(updates, fast)):
  File "/Users/sammuurr/PycharmProjects/GeekShop/venv/lib/python3.9/site-packages/aiogram/dispatcher/dispatcher.py", line 235, in process_updates
    return await asyncio.gather(*tasks)
  File "/Users/sammuurr/PycharmProjects/GeekShop/venv/lib/python3.9/site-packages/aiogram/dispatcher/handler.py", line 116, in notify
    response = await handler_obj.handler(*args, **partial_data)
  File "/Users/sammuurr/PycharmProjects/GeekShop/venv/lib/python3.9/site-packages/aiogram/dispatcher/dispatcher.py", line 256, in process_update
    return await self.message_handlers.notify(update.message)
  File "/Users/sammuurr/PycharmProjects/GeekShop/venv/lib/python3.9/site-packages/aiogram/dispatcher/handler.py", line 116, in notify
    response = await handler_obj.handler(*args, **partial_data)
  File "/Users/sammuurr/PycharmProjects/GeekShop/handlers/text_handlers/main_menu/question.py", line 30, in process_question_request
    await bot.send_message(message.reply_to_message.forward_from.id, "Ответ на ваше обращение: \n\n" + message.text)
AttributeError: 'NoneType' object has no attribute 'forward_from'
[2022-07-03 13:54:28,227] - [WARNING] -->  Goodbye!
[2022-07-03 14:02:23,883] - [WARNING] -->  Goodbye!
[2022-07-03 14:06:07,183] - [WARNING] -->  Goodbye!
[2022-07-03 14:06:37,437] - [WARNING] -->  Goodbye!
[2022-07-03 14:07:11,432] - [WARNING] -->  Goodbye!
[2022-07-03 14:08:06,012] - [WARNING] -->  Goodbye!
[2022-07-03 14:09:17,380] - [WARNING] -->  Goodbye!
[2022-07-03 14:11:32,922] - [WARNING] -->  Goodbye!
[2022-07-03 14:30:56,484] - [ERROR] -->  Cause exception while getting updates.
Traceback (most recent call last):
  File "/Users/sammuurr/PycharmProjects/GeekShop/venv/lib/python3.9/site-packages/aiogram/dispatcher/dispatcher.py", line 381, in start_polling
    updates = await self.bot.get_updates(
  File "/Users/sammuurr/PycharmProjects/GeekShop/venv/lib/python3.9/site-packages/aiogram/bot/bot.py", line 110, in get_updates
    result = await self.request(api.Methods.GET_UPDATES, payload)
  File "/Users/sammuurr/PycharmProjects/GeekShop/venv/lib/python3.9/site-packages/aiogram/bot/base.py", line 231, in request
    return await api.make_request(await self.get_session(), self.server, self.__token, method, data, files,
  File "/Users/sammuurr/PycharmProjects/GeekShop/venv/lib/python3.9/site-packages/aiogram/bot/api.py", line 139, in make_request
    async with session.post(url, data=req, **kwargs) as response:
  File "/Users/sammuurr/PycharmProjects/GeekShop/venv/lib/python3.9/site-packages/aiohttp/client.py", line 1138, in __aenter__
    self._resp = await self._coro
  File "/Users/sammuurr/PycharmProjects/GeekShop/venv/lib/python3.9/site-packages/aiohttp/client.py", line 559, in _request
    await resp.start(conn)
  File "/Users/sammuurr/PycharmProjects/GeekShop/venv/lib/python3.9/site-packages/aiohttp/client_reqrep.py", line 913, in start
    self._continue = None
  File "/Users/sammuurr/PycharmProjects/GeekShop/venv/lib/python3.9/site-packages/aiohttp/helpers.py", line 721, in __exit__
    raise asyncio.TimeoutError from None
asyncio.exceptions.TimeoutError
[2022-07-03 14:38:09,570] - [WARNING] -->  Goodbye!
[2022-07-03 14:38:35,838] - [WARNING] -->  Goodbye!
[2022-07-03 14:40:13,309] - [WARNING] -->  Goodbye!
[2022-07-03 15:05:06,244] - [WARNING] -->  Goodbye!
[2022-07-03 15:19:42,044] - [WARNING] -->  Goodbye!
[2022-07-03 15:23:02,520] - [WARNING] -->  Goodbye!
[2022-07-03 15:23:53,357] - [WARNING] -->  Goodbye!
[2022-07-03 15:24:23,186] - [WARNING] -->  Goodbye!
